<?xml version="1.0" ?>
<robot name="converted_robot">
   <link name="world" />

   <!-- Prismatic joints for translations -->
   <joint type="prismatic" name="translate_x_joint">
      <parent link="world" />
      <child link="joint_tx_link" />
      <origin xyz="0 0 0" rpy="0 0 0" />
      <axis xyz="1 0 0" />
      <limit effort="20.0" lower="-1.0" upper="1.0" velocity="5.0"/>
   </joint>

   <joint type="prismatic" name="translate_y_joint">
      <parent link="joint_tx_link" />
      <child link="joint_ty_link" />
      <origin xyz="0 0 0" rpy="0 0 0" />
      <axis xyz="0 1 0" />
      <limit effort="20.0" lower="-1.0" upper="1.0" velocity="5.0"/>
   </joint>

   <joint type="prismatic" name="translate_z_joint">
      <parent link="joint_ty_link" />
      <child link="joint_tz_link" />
      <origin xyz="0 0 0" rpy="0 0 0" />
      <axis xyz="0 0 1" />
      <limit effort="20.0" lower="-1.0" upper="1.0" velocity="5.0"/>
   </joint>

   <!-- Revolute joints for rotations -->
   <joint type="revolute" name="rotate_x_joint">
      <parent link="joint_tz_link" />
      <child link="joint_rx_link" />
      <origin xyz="0 0 0" rpy="0 0 0" />
      <axis xyz="1 0 0" />
      <limit effort="100" lower="-3.141593" upper="3.141593" velocity="100"/>
   </joint>

   <joint type="revolute" name="rotate_y_joint">
      <parent link="joint_rx_link" />
      <child link="joint_ry_link" />
      <origin xyz="0 0 0" rpy="0 0 0" />
      <axis xyz="0 1 0" />
      <limit effort="100" lower="-3.141593" upper="3.141593" velocity="100"/>
   </joint>

   <joint type="revolute" name="rotate_z_joint">
      <parent link="joint_ry_link" />
      <child link="joint_rz_link" />
      <origin xyz="0 0 0" rpy="0 0 0" />
      <axis xyz="0 0 1" />
      <limit effort="100" lower="-3.141593" upper="3.141593" velocity="100"/>
   </joint>

   <!-- Empty link definitions for the new joints -->
   <link name="joint_tx_link" />
   <link name="joint_ty_link" />
   <link name="joint_tz_link" />
   <link name="joint_rx_link" />
   <link name="joint_ry_link" />
   <link name="joint_rz_link" />

   <joint type="fixed" name="wrist_fixed">
      <parent link="joint_rz_link" />
      <child link="lunate" />
      <origin xyz="0 0 0" rpy="0 0 0" />
   </joint>
   <link name="lunate">
      <inertial>
         <origin xyz="0 0 0" rpy="0 0 0 " />
         <mass value="0.0012000263535597198" />
         <inertia ixx="0.0001" iyy="0.0001" izz="0.0001" ixy="0" ixz="0" iyz="0" />
      </inertial>
      <visual name="lunate">
         <origin xyz="0.0 0.0 0.0" rpy="0 0 0" />
         <geometry>
            <mesh filename="file:///home/haochen/catkin_ws/src/relaxed_ik_ros1/relaxed_ik_core/configs/urdfs/meshes/lunate.stl" scale="1.1486480425226826 1.1486480425226826 1.1486480425226826" />
         </geometry>
         <material name="white" />
      </visual>
   </link>
   <link name="scaphoid">
      <inertial>
         <origin xyz="0.0 0.0 0.0" rpy="0.0 0.0 0.0" />
         <mass value="0.02" />
         <inertia ixx="0.0001" iyy="0.0001" izz="0.0001" ixy="0" ixz="0" iyz="0" />
      </inertial>
      <visual name="scaphoid">
         <origin xyz="-2.7381929196923456e-05 -1.0358979807433321e-05 4.4037987240527154e-05" rpy="-0.5692290431693718 -0.33878345041747715 0.21369142489696064" />
         <geometry>
            <mesh filename="file:///home/haochen/catkin_ws/src/relaxed_ik_ros1/relaxed_ik_core/configs/urdfs/meshes/scaphoid.stl" scale="1.1486480425226826 1.1486480425226826 1.1486480425226826" />
         </geometry>
         <material name="white" />
      </visual>
   </link>
   <joint type="fixed" name="lunate2scaphoid_fixed">
      <parent link="lunate" />
      <child link="scaphoid" />
      <origin xyz="0.014180060084942516 -0.005127564861821255 -0.001440404645323444" rpy="0.0 0.0 0.0" />
   </joint>
   <link name="pisiform">
      <inertial>
         <origin xyz="0.0 0.0 0.0" rpy="0.0 0.0 0.0" />
         <mass value="0.02" />
         <inertia ixx="0.0001" iyy="0.0001" izz="0.0001" ixy="0" ixz="0" iyz="0" />
      </inertial>
      <visual name="pisiform">
         <origin xyz="0.0020423990550083038 -0.00104227212290906 -8.258993424585364e-05" rpy="1.2462055088005255 0.49559439583995424 -0.34929645069987836" />
         <geometry>
            <mesh filename="file:///home/haochen/catkin_ws/src/relaxed_ik_ros1/relaxed_ik_core/configs/urdfs/meshes/pisiform.stl" scale="1.1486480425226826 1.1486480425226826 1.1486480425226826" />
         </geometry>
         <material name="white" />
      </visual>
   </link>
   <joint type="fixed" name="lunate2pisiform_fixed">
      <parent link="lunate" />
      <child link="pisiform" />
      <origin xyz="-0.015378099993293676 -0.011355534548379242 -0.012167628714442777" rpy="0.0 0.0 0.0" />
   </joint>
   <link name="triquetrum">
      <inertial>
         <origin xyz="0.0 0.0 0.0" rpy="0.0 0.0 0.0" />
         <mass value="0.02" />
         <inertia ixx="0.0001" iyy="0.0001" izz="0.0001" ixy="0" ixz="0" iyz="0" />
      </inertial>
      <visual name="triquetrum">
         <origin xyz="6.812391269170598e-07 -1.2894266454457984e-06 -3.897970627994129e-06" rpy="1.9269139677822995 -0.29745876180457564 -0.5516387254770375" />
         <geometry>
            <mesh filename="file:///home/haochen/catkin_ws/src/relaxed_ik_ros1/relaxed_ik_core/configs/urdfs/meshes/triquetrum.stl" scale="1.1486480425226826 1.1486480425226826 1.1486480425226826" />
         </geometry>
         <material name="white" />
      </visual>
   </link>
   <joint type="fixed" name="lunate2triquetrum_fixed">
      <parent link="lunate" />
      <child link="triquetrum" />
      <origin xyz="-0.01238702049056461 -0.008613711670877596 -0.001480607326811738" rpy="0.0 0.0 0.0" />
   </joint>
   <link name="capitate">
      <inertial>
         <origin xyz="2.4997529376086936e-06 -4.319736123192584e-06 1.3404175140860993e-06" rpy="1.2103081004613072 -0.2920747955988763 -0.020398215496376104" />
         <mass value="0.001912230829037991" />
         <inertia ixx="0.0001" iyy="0.0001" izz="0.0001" ixy="0" ixz="0" iyz="0" />
      </inertial>
      <visual name="capitate">
         <origin xyz="2.8713363185745515e-06 -4.961856442119683e-06 1.5396679537181183e-06" rpy="1.2103081004613072 -0.29207479559887606 -0.020398215496375882" />
         <geometry>
            <mesh filename="file:///home/haochen/catkin_ws/src/relaxed_ik_ros1/relaxed_ik_core/configs/urdfs/meshes/capitate.stl" scale="1.1486480425226826 1.1486480425226826 1.1486480425226826" />
         </geometry>
         <material name="white" />
      </visual>
   </link>
   <joint type="fixed" name="lunate2capitate_fixed">
      <parent link="lunate" />
      <child link="capitate" />
      <origin xyz="0.004585402985750549 -0.017291747632136464 0.0026729039949502827" rpy="0.0 0.0 0.0" />
   </joint>
   <link name="trapezium">
      <inertial>
         <origin xyz="0.0 0.0 0.0" rpy="0.0 0.0 0.0" />
         <mass value="0.02" />
         <inertia ixx="0.0001" iyy="0.0001" izz="0.0001" ixy="0" ixz="0" iyz="0" />
      </inertial>
      <visual name="trapezium">
         <origin xyz="-6.52419296089787e-06 1.754874978953968e-06 -8.429878867173221e-07" rpy="-0.25650854392346234 -0.8000548292338777 2.2561533548010577" />
         <geometry>
            <mesh filename="file:///home/haochen/catkin_ws/src/relaxed_ik_ros1/relaxed_ik_core/configs/urdfs/meshes/trapezium.stl" scale="1.1486480425226826 1.1486480425226826 1.1486480425226826" />
         </geometry>
         <material name="white" />
      </visual>
   </link>
   <joint type="fixed" name="capitate2trapezium_fixed">
      <parent link="capitate" />
      <child link="trapezium" />
      <origin xyz="0.017566274514299384 -0.005248172906286137 -0.01184026402232381" rpy="0.0 0.0 0.0" />
   </joint>
   <link name="firstmc">
      <inertial>
         <origin xyz="0.01309968089388166 -0.0068745282609964375 -0.009698928892781572" rpy="-2.1572247499833628 -0.31560297757072453 -1.7510692763715643" />
         <mass value="0.016" />
         <inertia ixx="0.0001" iyy="0.0001" izz="0.0001" ixy="0" ixz="0" iyz="0" />
      </inertial>
      <visual name="1mc">
         <origin xyz="0.016022886860634612 -0.00832092393285486 -0.010080336290005914" rpy="-2.237451597882739 -0.5181491466513541 -1.6277365169800728" />
         <geometry>
            <mesh filename="file:///home/haochen/catkin_ws/src/relaxed_ik_ros1/relaxed_ik_core/configs/urdfs/meshes/1mc.stl" scale="1.1486480425226826 1.1486480425226826 1.1486480425226826" />
         </geometry>
         <material name="white" />
      </visual>
   </link>
   <link name="cmc_abduction_dummy">
      <inertial>
         <origin xyz="0.0 0.0 0.0" rpy="-0.7286789533902661 0.04241170412851947 -0.01617642349516324" />
         <mass value="0.001" />
         <inertia ixx="1e-09" iyy="1e-09" izz="1e-09" ixy="0" ixz="0" iyz="0" />
      </inertial>
   </link>
   <joint type="revolute" name="cmc_abduction">
      <parent link="trapezium" />
      <child link="cmc_abduction_dummy" />
      <origin xyz="0.008270265906163315 -0.006202699429622487 -0.0028716201063067066" rpy="0.7286789533902661 -0.042411704128519245 -0.01617642349516324" />
      <axis xyz="0 0 1" />
      <limit lower="-0.5" upper="0.78" effort="100" velocity="100" />
   </joint>
   <joint type="revolute" name="cmc_flexion">
      <parent link="cmc_abduction_dummy" />
      <child link="firstmc" />
      <origin xyz="0.0 0.0 0.0" rpy="-1.7353556432102104 0.24272282231633158 -0.5745472836968706" />
      <axis xyz="0 0 1" />
      <limit lower="-0.78" upper="0.7" effort="100" velocity="100" />
   </joint>
   <link name="proximal_thumb">
      <inertial>
         <origin xyz="0.009175945436263407 -0.017323667062881923 -0.003637662002596822" rpy="2.193467119650854 0.33126827277613535 1.3835402268256396" />
         <mass value="0.0079" />
         <inertia ixx="0.0001" iyy="0.0001" izz="0.0001" ixy="0" ixz="0" iyz="0" />
      </inertial>
      <visual name="thumbprox">
         <origin xyz="0.00938848705426134 -0.0183600285502546 -0.0036046742862456908" rpy="1.751348942319772 -0.12389205032924067 0.43579123948592824" />
         <geometry>
            <mesh filename="file:///home/haochen/catkin_ws/src/relaxed_ik_ros1/relaxed_ik_core/configs/urdfs/meshes/thumbprox.stl" scale="1.1486480425226826 1.1486480425226826 1.1486480425226826" />
         </geometry>
         <material name="white" />
      </visual>
   </link>
   <joint type="revolute" name="mp_flexion">
      <parent link="firstmc" />
      <child link="proximal_thumb" />
      <origin xyz="0.03129639228640301 -0.015313902373446452 -0.0219771755528549" rpy="1.2527425101647096 -0.5549106329448805 -0.37755264808441874" />
      <axis xyz="0 0 1" />
      <limit lower="-0.785398" upper="0.698132" effort="100" velocity="100" />
   </joint>
   <link name="distal_thumb">
      <inertial>
         <origin xyz="0.00550527089824059 -0.011306835175704626 0.0008529188979227702" rpy="1.55414831514287 -0.6236827888860802 0.4187783633237224" />
         <mass value="0.003" />
         <inertia ixx="0.0001" iyy="0.0001" izz="0.0001" ixy="0" ixz="0" iyz="0" />
      </inertial>
      <visual name="thumbdist">
         <origin xyz="0.004781948198670034 -0.011211845491539923 0.001113968291602856" rpy="1.522079931177215 -0.031788312575904865 0.4785542231651294" />
         <geometry>
            <mesh filename="file:///home/haochen/catkin_ws/src/relaxed_ik_ros1/relaxed_ik_core/configs/urdfs/meshes/thumbdist.stl" scale="1.1486480425226826 1.1486480425226826 1.1486480425226826" />
         </geometry>
         <material name="white" />
      </visual>
   </link>
   <joint type="revolute" name="ip_flexion">
      <parent link="proximal_thumb" />
      <child link="distal_thumb" />
      <origin xyz="0.015303616763315903 -0.031626761480794775 -0.006618228243097208" rpy="0.2947943417533358 0.032709979997034955 -0.01102290149135593" />
      <axis xyz="0 0 1" />
      <limit lower="-1.309" upper="0.436332" effort="100" velocity="100" />
   </joint>
   <link name="trapezoid">
      <inertial>
         <origin xyz="0.0 0.0 0.0" rpy="0.0 0.0 0.0" />
         <mass value="0.02" />
         <inertia ixx="0.0001" iyy="0.0001" izz="0.0001" ixy="0" ixz="0" iyz="0" />
      </inertial>
      <visual name="trapezoid">
         <origin xyz="1.5780993088395719e-06 -1.6966149991049483e-06 2.1724760893410968e-07" rpy="0.27598761251820697 0.5558008487263413 0.19209924739735612" />
         <geometry>
            <mesh filename="file:///home/haochen/catkin_ws/src/relaxed_ik_ros1/relaxed_ik_core/configs/urdfs/meshes/trapezoid.stl" scale="1.1486480425226826 1.1486480425226826 1.1486480425226826" />
         </geometry>
         <material name="white" />
      </visual>
   </link>
   <joint type="fixed" name="capitate2trapezoid_fixed">
      <parent link="capitate" />
      <child link="trapezoid" />
      <origin xyz="0.010502089052784887 -0.004665808348727136 -0.00283026877677589" rpy="0.0 0.0 0.0" />
   </joint>
   <link name="hamate">
      <inertial>
         <origin xyz="0.0 0.0 0.0" rpy="0.0 0.0 0.0" />
         <mass value="0.02" />
         <inertia ixx="0.0001" iyy="0.0001" izz="0.0001" ixy="0" ixz="0" iyz="0" />
      </inertial>
      <visual name="hamate">
         <origin xyz="-1.3189802766648271e-05 -1.5780058425544745e-06 1.7467973266791726e-06" rpy="1.941141541594031 -0.4553846643318562 -0.6664160632978575" />
         <geometry>
            <mesh filename="file:///home/haochen/catkin_ws/src/relaxed_ik_ros1/relaxed_ik_core/configs/urdfs/meshes/hamate.stl" scale="1.1486480425226826 1.1486480425226826 1.1486480425226826" />
         </geometry>
         <material name="white" />
      </visual>
   </link>
   <joint type="fixed" name="capitate2hamate_fixed">
      <parent link="capitate" />
      <child link="hamate" />
      <origin xyz="-0.012599520378431305 -0.002865876866094093 -0.000861486031892012" rpy="0.0 0.0 0.0" />
   </joint>
   <link name="secondmc">
      <inertial>
         <origin xyz="0.0 0.0 0.0" rpy="0.0 0.0 0.0" />
         <mass value="0.02" />
         <inertia ixx="0.0001" iyy="0.0001" izz="0.0001" ixy="0" ixz="0" iyz="0" />
      </inertial>
      <visual name="2mc">
         <origin xyz="-0.00012040663444485341 0.00014517430010183328 -0.0001606212732707591" rpy="-1.2288611407496322 -1.0576482637579705 2.9957695490133696" />
         <geometry>
            <mesh filename="file:///home/haochen/catkin_ws/src/relaxed_ik_ros1/relaxed_ik_core/configs/urdfs/meshes/2mc.stl" scale="1.1486480425226826 1.1486480425226826 1.1486480425226826" />
         </geometry>
         <material name="white" />
      </visual>
   </link>
   <joint type="fixed" name="capitate2secondmc_fixed">
      <parent link="capitate" />
      <child link="secondmc" />
      <origin xyz="0.016867896504445593 -0.04321213935970332 0.005779996949974139" rpy="0.0 0.0 0.0" />
   </joint>
   <link name="proxph2">
      <inertial>
         <origin xyz="0.0 0.0 0.0" rpy="0.0861356540103359 0.05502674551362019 0.0023719461216022628" />
         <mass value="0.01" />
         <inertia ixx="0.0001" iyy="0.0001" izz="0.0001" ixy="0" ixz="0" iyz="0" />
      </inertial>
      <visual name="2proxph">
         <origin xyz="0.0051375441366975074 -0.026105067500285895 0.0028485870305339283" rpy="1.3231070703266785 -1.2754347723112274 0.4086444603936795" />
         <geometry>
            <mesh filename="file:///home/haochen/catkin_ws/src/relaxed_ik_ros1/relaxed_ik_core/configs/urdfs/meshes/2proxph.stl" scale="1.1486480425226826 1.1486480425226826 1.1486480425226826" />
         </geometry>
         <material name="white" />
      </visual>
   </link>
   <link name="mcp2_flexion_dummy">
      <inertial>
         <origin xyz="0.0 0.0 0.0" rpy="1.570796326794898 -1.4708802086674053 -1.4708802086674067" />
         <mass value="0.001" />
         <inertia ixx="1e-09" iyy="1e-09" izz="1e-09" ixy="0" ixz="0" iyz="0" />
      </inertial>
   </link>
   <joint type="revolute" name="mcp2_flexion">
      <parent link="secondmc" />
      <child link="mcp2_flexion_dummy" />
      <origin xyz="0.004021416796871912 -0.032441266664968126 0.004158105913932111" rpy="-1.5707963267948977 1.4708802086674053 -1.4708802086674064" />
      <axis xyz="0 0 1" />
      <limit lower="0.0" upper="1.5708" effort="100" velocity="100" />
   </joint>
   <joint type="revolute" name="mcp2_abduction">
      <parent link="mcp2_flexion_dummy" />
      <child link="proxph2" />
      <origin xyz="0.0 0.0 0.0" rpy="1.996706135703522 -1.4588445662369582 -1.9856122470713664" />
      <axis xyz="0 0 1" />
      <limit lower="-0.261799" upper="0.261799" effort="100" velocity="100" />
   </joint>
   <link name="midph2">
      <inertial>
         <origin xyz="0.0 0.0 0.0" rpy="2.673926789498819 -1.347488638214627 -2.561714096685443" />
         <mass value="0.003" />
         <inertia ixx="0.0001" iyy="0.0001" izz="0.0001" ixy="0" ixz="0" iyz="0" />
      </inertial>
      <visual name="2midph">
         <origin xyz="0.0010981405744331203 -0.015731082768666933 0.0002862995543351543" rpy="-1.5630400763369505 -0.0019507371444631438 -3.1305336815452" />
         <geometry>
            <mesh filename="file:///home/haochen/catkin_ws/src/relaxed_ik_ros1/relaxed_ik_core/configs/urdfs/meshes/2midph.stl" scale="1.1486480425226826 1.1486480425226826 1.1486480425226826" />
         </geometry>
         <material name="white" />
      </visual>
   </link>
   <joint type="revolute" name="pm2_flexion">
      <parent link="proxph2" />
      <child link="midph2" />
      <origin xyz="0.008963802724527972 -0.04793519890568429 0.0038243567913669326" rpy="-3.1093030719372434 1.3265450030648043 -2.985625911527994" />
      <axis xyz="0 0 1" />
      <limit lower="0.0" upper="1.5708" effort="100" velocity="100" />
   </joint>
   <link name="distph2">
      <inertial>
         <origin xyz="0.0 0.0 0.0" rpy="1.5707963267948983 -1.47079632685829 -1.4707963268582915" />
         <mass value="0.002" />
         <inertia ixx="0.0001" iyy="0.0001" izz="0.0001" ixy="0" ixz="0" iyz="0" />
      </inertial>
      <visual name="2distph">
         <origin xyz="0.0006399561752212981 -0.009820984182418283 0.0002466383204659929" rpy="-1.5239710771919284 -0.03676633885392766 -3.140805196244449" />
         <geometry>
            <mesh filename="file:///home/haochen/catkin_ws/src/relaxed_ik_ros1/relaxed_ik_core/configs/urdfs/meshes/2distph.stl" scale="1.1486480425226826 1.1486480425226826 1.1486480425226826" />
         </geometry>
         <material name="white" />
      </visual>
   </link>
   <joint type="revolute" name="md2_flexion">
      <parent link="midph2" />
      <child link="distph2" />
      <origin xyz="0.0013930466537968441 -0.02883687720518117 0.0006023764869396378" rpy="0.0221383296958119 -0.1977786936551691 2.5098334244206405e-05" />
      <axis xyz="0 0 1" />
      <limit lower="0.0" upper="1.5708" effort="100" velocity="100" />
   </joint>
   <link name="thirdmc">
      <inertial>
         <origin xyz="0.0 0.0 0.0" rpy="0.0 0.0 0.0" />
         <mass value="0.02" />
         <inertia ixx="0.0001" iyy="0.0001" izz="0.0001" ixy="0" ixz="0" iyz="0" />
      </inertial>
      <visual name="3mc">
         <origin xyz="1.4041991268939994e-05 0.0005937060068091821 -0.00027660641897258383" rpy="1.4450266262998412 0.1803584102818272 -0.007490416792627297" />
         <geometry>
            <mesh filename="file:///home/haochen/catkin_ws/src/relaxed_ik_ros1/relaxed_ik_core/configs/urdfs/meshes/3mc.stl" scale="1.1486480425226826 1.1486480425226826 1.1486480425226826" />
         </geometry>
         <material name="white" />
      </visual>
   </link>
   <joint type="fixed" name="capitate2thirdmc_fixed">
      <parent link="capitate" />
      <child link="thirdmc" />
      <origin xyz="0.0005479051162833196 -0.045071800540547546 0.00847357660968983" rpy="0.0 0.0 0.0" />
   </joint>
   <link name="proxph3">
      <inertial>
         <origin xyz="0.0 0.0 0.0" rpy="0.0 0.1999995919289601 0.0" />
         <mass value="0.01" />
         <inertia ixx="0.0001" iyy="0.0001" izz="0.0001" ixy="0" ixz="0" iyz="0" />
      </inertial>
      <visual name="3proxph">
         <origin xyz="0.002237673034537285 -0.026750169029813774 0.0048321523975142135" rpy="1.1265372608123134 -1.2987544122063608 0.4693796480506728" />
         <geometry>
            <mesh filename="file:///home/haochen/catkin_ws/src/relaxed_ik_ros1/relaxed_ik_core/configs/urdfs/meshes/3proxph.stl" scale="1.1486480425226826 1.1486480425226826 1.1486480425226826" />
         </geometry>
         <material name="white" />
      </visual>
   </link>
   <link name="mcp3_flexion_dummy">
      <inertial>
         <origin xyz="0.0 0.0 0.0" rpy="0.0 -1.370796734865936 0.0" />
         <mass value="0.001" />
         <inertia ixx="1e-09" iyy="1e-09" izz="1e-09" ixy="0" ixz="0" iyz="0" />
      </inertial>
   </link>
   <joint type="revolute" name="mcp3_flexion">
      <parent link="thirdmc" />
      <child link="mcp3_flexion_dummy" />
      <origin xyz="0.0002756755302054438 -0.030197957037921327 0.00204229621960533" rpy="0.0 1.370796734865936 0.0" />
      <axis xyz="0 0 1" />
      <limit lower="0.0" upper="1.5708" effort="100" velocity="100" />
   </joint>
   <joint type="revolute" name="mcp3_abduction">
      <parent link="mcp3_flexion_dummy" />
      <child link="proxph3" />
      <origin xyz="0.0 0.0 0.0" rpy="0.0 -1.570796326794896 0.0" />
      <axis xyz="0 0 1" />
      <limit lower="-0.261799" upper="0.261799" effort="100" velocity="100" />
   </joint>
   <link name="midph3">
      <inertial>
         <origin xyz="0.0 0.0 0.0" rpy="0.0 0.0 0.0" />
         <mass value="0.002" />
         <inertia ixx="0.0001" iyy="0.0001" izz="0.0001" ixy="0" ixz="0" iyz="0" />
      </inertial>
      <visual name="3midph">
         <origin xyz="0.0007829275525715381 -0.017087217488224248 0.0018236916944641694" rpy="-0.7901456653983332 -1.4979259934357858 2.4117147631811826" />
         <geometry>
            <mesh filename="file:///home/haochen/catkin_ws/src/relaxed_ik_ros1/relaxed_ik_core/configs/urdfs/meshes/3midph.stl" scale="1.1486480425226826 1.1486480425226826 1.1486480425226826" />
         </geometry>
         <material name="white" />
      </visual>
   </link>
   <joint type="revolute" name="pm3_flexion">
      <parent link="proxph3" />
      <child link="midph3" />
      <origin xyz="0.0032791804486541182 -0.05078287860797032 0.006636901655556221" rpy="0.0 0.1999995919289601 0.0" />
      <axis xyz="1.0 0.0 0.0" />
      <limit lower="0.0" upper="1.5708" effort="100" velocity="100" />
   </joint>
   <link name="distph3">
      <inertial>
         <origin xyz="0.0 0.0 0.0" rpy="0.0 0.0 0.0" />
         <mass value="0.002" />
         <inertia ixx="0.0001" iyy="0.0001" izz="0.0001" ixy="0" ixz="0" iyz="0" />
      </inertial>
      <visual name="3distph">
         <origin xyz="0.000720605309227018 -0.009831150678150248 -3.730927176514851e-05" rpy="0.4079397820603109 -1.4851549016387633 1.2108481043436288" />
         <geometry>
            <mesh filename="file:///home/haochen/catkin_ws/src/relaxed_ik_ros1/relaxed_ik_core/configs/urdfs/meshes/3distph.stl" scale="1.1486480425226826 1.1486480425226826 1.1486480425226826" />
         </geometry>
         <material name="white" />
      </visual>
   </link>
   <joint type="revolute" name="md3_flexion">
      <parent link="midph3" />
      <child link="distph3" />
      <origin xyz="0.0015679045780434616 -0.03336477969115636 0.002244458275089322" rpy="0.0 0.0 0.0" />
      <axis xyz="1.0 0.0 0.0" />
      <limit lower="0.0" upper="1.5708" effort="100" velocity="100" />
   </joint>
   <link name="fourthmc">
      <inertial>
         <origin xyz="0.0 0.0 0.0" rpy="0.0 0.0 0.0" />
         <mass value="0.02" />
         <inertia ixx="0.0001" iyy="0.0001" izz="0.0001" ixy="0" ixz="0" iyz="0" />
      </inertial>
      <visual name="4mc">
         <origin xyz="5.0312314089011366e-05 0.0006110152739212508 -0.0001915579659817326" rpy="1.5268660941250807 -0.37727025049358964 -0.07031755099911208" />
         <geometry>
            <mesh filename="file:///home/haochen/catkin_ws/src/relaxed_ik_ros1/relaxed_ik_core/configs/urdfs/meshes/4mc.stl" scale="1.1486480425226826 1.1486480425226826 1.1486480425226826" />
         </geometry>
         <material name="white" />
      </visual>
   </link>
   <joint type="fixed" name="capitate2fourthmc_fixed">
      <parent link="capitate" />
      <child link="fourthmc" />
      <origin xyz="-0.013836614320228233 -0.046542070034976575 0.004035200573382184" rpy="0.0 0.0 0.0" />
   </joint>
   <link name="proxph4">
      <inertial>
         <origin xyz="0.0 0.0 0.0" rpy="0.0 0.4500004640280282 0.0" />
         <mass value="0.01" />
         <inertia ixx="0.0001" iyy="0.0001" izz="0.0001" ixy="0" ixz="0" iyz="0" />
      </inertial>
      <visual name="4proxph">
         <origin xyz="-0.0015305635334287291 -0.02480155634565551 0.0024381744741931357" rpy="0.6976319582938976 -1.4758909364414674 0.797666297432624" />
         <geometry>
            <mesh filename="file:///home/haochen/catkin_ws/src/relaxed_ik_ros1/relaxed_ik_core/configs/urdfs/meshes/4proxph.stl" scale="1.1486480425226826 1.1486480425226826 1.1486480425226826" />
         </geometry>
         <material name="white" />
      </visual>
   </link>
   <link name="mcp4_flexion_dummy">
      <inertial>
         <origin xyz="0.0 0.0 0.0" rpy="0.0 -1.120795862766868 0.0" />
         <mass value="0.001" />
         <inertia ixx="1e-09" iyy="1e-09" izz="1e-09" ixy="0" ixz="0" iyz="0" />
      </inertial>
   </link>
   <joint type="revolute" name="mcp4_flexion">
      <parent link="fourthmc" />
      <child link="mcp4_flexion_dummy" />
      <origin xyz="-0.002102025917816509 -0.02721032347931983 -0.0001987161113564241" rpy="0.0 1.1207958627668684 0.0" />
      <axis xyz="0 0 1" />
      <limit lower="0.0" upper="1.5708" effort="100" velocity="100" />
   </joint>
   <joint type="revolute" name="mcp4_abduction">
      <parent link="mcp4_flexion_dummy" />
      <child link="proxph4" />
      <origin xyz="0.0 0.0 0.0" rpy="0.0 -1.570796326794896 0.0" />
      <axis xyz="0 0 1" />
      <limit lower="-0.261799" upper="0.261799" effort="100" velocity="100" />
   </joint>
   <link name="midph4">
      <inertial>
         <origin xyz="0.0 0.0 0.0" rpy="0.0 -1.1707966444174693 0.0" />
         <mass value="0.003" />
         <inertia ixx="0.0001" iyy="0.0001" izz="0.0001" ixy="0" ixz="0" iyz="0" />
      </inertial>
      <visual name="4midph">
         <origin xyz="-0.001353088088978765 -0.015064657847648759 -0.0014358467691289731" rpy="-1.624420311140701 -0.005298798978447428 3.0977891945924623" />
         <geometry>
            <mesh filename="file:///home/haochen/catkin_ws/src/relaxed_ik_ros1/relaxed_ik_core/configs/urdfs/meshes/4midph.stl" scale="1.1486480425226826 1.1486480425226826 1.1486480425226826" />
         </geometry>
         <material name="white" />
      </visual>
   </link>
   <joint type="revolute" name="pm4_flexion">
      <parent link="proxph4" />
      <child link="midph4" />
      <origin xyz="-0.0029770056462484666 -0.046238826951750585 0.003153798086735828" rpy="3.141592653589793 1.5207955451442956 3.141592653589793" />
      <axis xyz="0 0 1" />
      <limit lower="0.0" upper="1.5708" effort="100" velocity="100" />
   </joint>
   <link name="distph4">
      <inertial>
         <origin xyz="0.0 0.0 0.0" rpy="0.0 -0.9707969349430002 0.0" />
         <mass value="0.002" />
         <inertia ixx="0.0001" iyy="0.0001" izz="0.0001" ixy="0" ixz="0" iyz="0" />
      </inertial>
      <visual name="4distph">
         <origin xyz="-0.001419510081331001 -0.010166091201686147 6.590653983947982e-05" rpy="-1.5832780312239776 -0.030396363417948713 2.965276549615234" />
         <geometry>
            <mesh filename="file:///home/haochen/catkin_ws/src/relaxed_ik_ros1/relaxed_ik_core/configs/urdfs/meshes/4distph.stl" scale="1.1486480425226826 1.1486480425226826 1.1486480425226826" />
         </geometry>
         <material name="white" />
      </visual>
   </link>
   <joint type="revolute" name="md4_flexion">
      <parent link="midph4" />
      <child link="distph4" />
      <origin xyz="-0.0016320439711825436 -0.02847383632609478 -0.002199495880604861" rpy="0.0 -0.199999709474469 0.0" />
      <axis xyz="0 0 1" />
      <limit lower="0.0" upper="1.5708" effort="100" velocity="100" />
   </joint>
   <link name="fifthmc">
      <inertial>
         <origin xyz="0.0 0.0 0.0" rpy="0.0 0.0 0.0" />
         <mass value="0.02" />
         <inertia ixx="0.0001" iyy="0.0001" izz="0.0001" ixy="0" ixz="0" iyz="0" />
      </inertial>
      <visual name="5mc">
         <origin xyz="0.00022361373693416503 0.00048072589841007 -0.00014777245296331376" rpy="1.6537260233892077 -1.161764483067726 -0.20407074680325432" />
         <geometry>
            <mesh filename="file:///home/haochen/catkin_ws/src/relaxed_ik_ros1/relaxed_ik_core/configs/urdfs/meshes/5mc.stl" scale="1.1486480425226826 1.1486480425226826 1.1486480425226826" />
         </geometry>
         <material name="white" />
      </visual>
   </link>
   <joint type="fixed" name="capitate2fifthmc_fixed">
      <parent link="capitate" />
      <child link="fifthmc" />
      <origin xyz="-0.025150797539076657 -0.0398385600588142 -0.004844997443360676" rpy="0.0 0.0 0.0" />
   </joint>
   <link name="proxph5">
      <inertial>
         <origin xyz="0.0 0.0 0.0" rpy="0.0 0.5999993918518967 0.0" />
         <mass value="0.005" />
         <inertia ixx="0.0001" iyy="0.0001" izz="0.0001" ixy="0" ixz="0" iyz="0" />
      </inertial>
      <visual name="5proxph">
         <origin xyz="-0.003908473121372411 -0.02219360602072662 0.0010123208496313446" rpy="-1.4569822139036401 -1.381514906722609 2.885196567174457" />
         <geometry>
            <mesh filename="file:///home/haochen/catkin_ws/src/relaxed_ik_ros1/relaxed_ik_core/configs/urdfs/meshes/5proxph.stl" scale="1.1486480425226826 1.1486480425226826 1.1486480425226826" />
         </geometry>
         <material name="white" />
      </visual>
   </link>
   <link name="mcp5_flexion_dummy">
      <inertial>
         <origin xyz="0.0 0.0 0.0" rpy="0.0 -0.9707969349430002 0.0" />
         <mass value="0.001" />
         <inertia ixx="1e-09" iyy="1e-09" izz="1e-09" ixy="0" ixz="0" iyz="0" />
      </inertial>
   </link>
   <joint type="revolute" name="mcp5_flexion">
      <parent link="fifthmc" />
      <child link="mcp5_flexion_dummy" />
      <origin xyz="-0.001834390923908724 -0.02461667619930361 -0.0017183774716139331" rpy="0.0 0.9707969349430003 0.0" />
      <axis xyz="0 0 1" />
      <limit lower="0.0" upper="1.5708" effort="100" velocity="100" />
   </joint>
   <joint type="revolute" name="mcp5_abduction">
      <parent link="mcp5_flexion_dummy" />
      <child link="proxph5" />
      <origin xyz="0.0 0.0 0.0" rpy="0.0 -1.5707963267948963 0.0" />
      <axis xyz="0 0 1" />
      <limit lower="-0.261799" upper="0.261799" effort="100" velocity="100" />
   </joint>
   <link name="midph5">
      <inertial>
         <origin xyz="0.0 0.0 0.0" rpy="0.0 -0.9707969349430002 0.0" />
         <mass value="0.002" />
         <inertia ixx="0.0001" iyy="0.0001" izz="0.0001" ixy="0" ixz="0" iyz="0" />
      </inertial>
      <visual name="5midph">
         <origin xyz="0.00022080340054868243 -0.01352025937811501 -0.0023992904475566693" rpy="-1.7327462170365329 0.14316308891352914 3.08764894477981" />
         <geometry>
            <mesh filename="file:///home/haochen/catkin_ws/src/relaxed_ik_ros1/relaxed_ik_core/configs/urdfs/meshes/5midph.stl" scale="1.1486480425226826 1.1486480425226826 1.1486480425226826" />
         </geometry>
         <material name="white" />
      </visual>
   </link>
   <joint type="revolute" name="pm5_flexion">
      <parent link="proxph5" />
      <child link="midph5" />
      <origin xyz="-0.0068718475167199354 -0.04084937033623416 0.0006944757577670242" rpy="-0.0 1.5707963267948966 0.0" />
      <axis xyz="0 0 1" />
      <limit lower="0.0" upper="1.5708" effort="100" velocity="100" />
   </joint>
   <link name="distph5">
      <inertial>
         <origin xyz="0.0 0.0 0.0" rpy="-0.3006875686285624 -0.6985554313998293 0.11023436132302193" />
         <mass value="0.001" />
         <inertia ixx="0.0001" iyy="0.0001" izz="0.0001" ixy="0" ixz="0" iyz="0" />
      </inertial>
      <visual name="5distph">
         <origin xyz="-0.0011652293805427022 -0.009049505681676489 0.000513955888046416" rpy="-1.5131584280044281 -0.07399081576380362 2.9725845702930727" />
         <geometry>
            <mesh filename="file:///home/haochen/catkin_ws/src/relaxed_ik_ros1/relaxed_ik_core/configs/urdfs/meshes/5distph.stl" scale="1.1486480425226826 1.1486480425226826 1.1486480425226826" />
         </geometry>
         <material name="white" />
      </visual>
   </link>
   <joint type="revolute" name="md5_flexion">
      <parent link="midph5" />
      <child link="distph5" />
      <origin xyz="0.0002643515310665187 -0.023750595575241513 -0.004176520440067224" rpy="0.20638367854381953 -0.26826088009272797 0.08747994233519721" />
      <axis xyz="0 0 1" />
      <limit lower="0.0" upper="1.5708" effort="100" velocity="100" />
   </joint>
   <link name="THtip">
      <inertial>
         <origin xyz="0.0 0.0 0.0" rpy="0.0 0.0 0.0" />
         <mass value="0.001" />
         <inertia ixx="1e-09" iyy="1e-09" izz="1e-09" ixy="0" ixz="0" iyz="0" />
      </inertial>
   </link>
   <joint type="fixed" name="THtip_joint">
      <parent link="distal_thumb" />
      <child link="THtip" />
      <origin xyz="0.011304973256230661 -0.024710516495247227 0.002392744417495439" rpy="-0.500912540251172 0.05012299056598368 -0.012825373716091965" />
   </joint>
   <link name="IFtip">
      <inertial>
         <origin xyz="0.0 0.0 0.0" rpy="0.0 0.0 0.0" />
         <mass value="0.001" />
         <inertia ixx="1e-09" iyy="1e-09" izz="1e-09" ixy="0" ixz="0" iyz="0" />
      </inertial>
   </link>
   <joint type="fixed" name="IFtip_joint">
      <parent link="distph2" />
      <child link="IFtip" />
      <origin xyz="0.0020767067263732755 -0.020697797526362065 0.0002216969198405811" rpy="1.5707963267948983 -1.47079632685829 -1.4707963268582915" />
   </joint>
   <link name="MFtip">
      <inertial>
         <origin xyz="0.0 0.0 0.0" rpy="0.0 0.0 0.0" />
         <mass value="0.001" />
         <inertia ixx="1e-09" iyy="1e-09" izz="1e-09" ixy="0" ixz="0" iyz="0" />
      </inertial>
   </link>
   <joint type="fixed" name="MFtip_joint">
      <parent link="distph3" />
      <child link="MFtip" />
      <origin xyz="0.002297296085045365 -0.021824312807930967 -0.0011486480425226826" rpy="0.0 0.0 0.0" />
   </joint>
   <link name="RFtip">
      <inertial>
         <origin xyz="0.0 0.0 0.0" rpy="0.0 0.0 0.0" />
         <mass value="0.001" />
         <inertia ixx="1e-09" iyy="1e-09" izz="1e-09" ixy="0" ixz="0" iyz="0" />
      </inertial>
   </link>
   <joint type="fixed" name="RFtip_joint">
      <parent link="distph4" />
      <child link="RFtip" />
      <origin xyz="-0.0015965954281736284 -0.02067566476540829 -0.0002994456376664207" rpy="0.0 -0.9707969349430002 0.0" />
   </joint>
   <link name="LFtip">
      <inertial>
         <origin xyz="0.0 0.0 0.0" rpy="0.0 0.0 0.0" />
         <mass value="0.001" />
         <inertia ixx="1e-09" iyy="1e-09" izz="1e-09" ixy="0" ixz="0" iyz="0" />
      </inertial>
   </link>
   <joint type="fixed" name="LFtip_joint">
      <parent link="distph5" />
      <child link="LFtip" />
      <origin xyz="-0.00030315991633306173 -0.019825191984694294 0.0011696846527624262" rpy="-0.3006875686285624 -0.6985554313998293 0.11023436132302193" />
   </joint>
   <material name="white">
      <color rgba="1 1 1 1" />
   </material>

   <!-- Left hand -->
   <!-- Prismatic joints for translations -->
   <joint type="prismatic" name="translate_x_joint_left">
      <parent link="world" />
      <child link="joint_tx_link_left" />
      <origin xyz="0 0 0" rpy="0 0 0" />
      <axis xyz="1 0 0" />
      <limit effort="20.0" lower="-1.0" upper="1.0" velocity="5.0"/>
   </joint>

   <joint type="prismatic" name="translate_y_joint_left">
      <parent link="joint_tx_link_left" />
      <child link="joint_ty_link_left" />
      <origin xyz="0 0 0" rpy="0 0 0" />
      <axis xyz="0 1 0" />
      <limit effort="20.0" lower="-1.0" upper="1.0" velocity="5.0"/>
   </joint>

   <joint type="prismatic" name="translate_z_joint_left">
      <parent link="joint_ty_link_left" />
      <child link="joint_tz_link_left" />
      <origin xyz="0 0 0" rpy="0 0 0" />
      <axis xyz="0 0 1" />
      <limit effort="20.0" lower="-1.0" upper="1.0" velocity="5.0"/>
   </joint>

   <!-- Revolute joints for rotations -->
   <joint type="revolute" name="rotate_x_joint_left">
      <parent link="joint_tz_link_left" />
      <child link="joint_rx_link_left" />
      <origin xyz="0 0 0" rpy="0 0 0" />
      <axis xyz="1 0 0" />
      <limit effort="100" lower="-3.141593" upper="3.141593" velocity="100"/>
   </joint>

   <joint type="revolute" name="rotate_y_joint_left">
      <parent link="joint_rx_link_left" />
      <child link="joint_ry_link_left" />
      <origin xyz="0 0 0" rpy="0 0 0" />
      <axis xyz="0 1 0" />
      <limit effort="100" lower="-3.141593" upper="3.141593" velocity="100"/>
   </joint>

   <joint type="revolute" name="rotate_z_joint_left">
      <parent link="joint_ry_link_left" />
      <child link="joint_rz_link_left" />
      <origin xyz="0 0 0" rpy="0 0 0" />
      <axis xyz="0 0 1" />
      <limit effort="100" lower="-3.141593" upper="3.141593" velocity="100"/>
   </joint>

   <!-- Empty link definitions for the new joints -->
   <link name="joint_tx_link_left" />
   <link name="joint_ty_link_left" />
   <link name="joint_tz_link_left" />
   <link name="joint_rx_link_left" />
   <link name="joint_ry_link_left" />
   <link name="joint_rz_link_left" />

   <joint type="fixed" name="wrist_fixed_left">
      <parent link="joint_rz_link_left" />
      <child link="lunate_left" />
      <origin xyz="0.0 0.0 0.0" rpy="0.0 0.0 0.0" />
   </joint>
   <link name="lunate_left">
      <inertial>
         <origin xyz="0.0 0.0 0.0" rpy="0.0 0.0 0.0" />
         <mass value="0.0012000263535597198" />
         <inertia ixx="0.0001" iyy="0.0001" izz="0.0001" ixy="0" ixz="0" iyz="0" />
      </inertial>
      <visual name="lunate_left">
         <origin xyz="0.0 0.0 0.0" rpy="0.0 0.0 0.0" />
         <geometry>
            <mesh filename="file:///home/haochen/catkin_ws/src/relaxed_ik_ros1/relaxed_ik_core/configs/urdfs/meshes/lunate_left.stl" scale="1.1486480425226826 1.1486480425226826 1.1486480425226826" />
         </geometry>
         <material name="white" />
      </visual>
   </link>
   <link name="scaphoid_left">
      <inertial>
         <origin xyz="0.0 0.0 0.0" rpy="0.0 0.0 0.0" />
         <mass value="0.02" />
         <inertia ixx="0.0001" iyy="0.0001" izz="0.0001" ixy="0" ixz="0" iyz="0" />
      </inertial>
      <visual name="scaphoid_left">
         <origin xyz="2.7381929196927668e-05 -1.0358979807432913e-05 4.403798724052742e-05" rpy="-0.5692290431693717 0.33878345041747737 -0.2136914248969607" />
         <geometry>
            <mesh filename="file:///home/haochen/catkin_ws/src/relaxed_ik_ros1/relaxed_ik_core/configs/urdfs/meshes/scaphoid_left.stl" scale="1.1486480425226826 1.1486480425226826 1.1486480425226826" />
         </geometry>
         <material name="white" />
      </visual>
   </link>
   <joint type="fixed" name="lunate2scaphoid_fixed_left">
      <parent link="lunate_left" />
      <child link="scaphoid_left" />
      <origin xyz="-0.014180060084942516 -0.005127564861821255 -0.001440404645323444" rpy="0.0 0.0 0.0" />
   </joint>
   <link name="pisiform_left">
      <inertial>
         <origin xyz="0.0 0.0 0.0" rpy="0.0 0.0 0.0" />
         <mass value="0.02" />
         <inertia ixx="0.0001" iyy="0.0001" izz="0.0001" ixy="0" ixz="0" iyz="0" />
      </inertial>
      <visual name="pisiform_left">
         <origin xyz="-0.0020423990550083038 -0.00104227212290906 -8.258993424585526e-05" rpy="1.2462055088005255 -0.49559439583995424 0.3492964506998784" />
         <geometry>
            <mesh filename="file:///home/haochen/catkin_ws/src/relaxed_ik_ros1/relaxed_ik_core/configs/urdfs/meshes/pisiform_left.stl" scale="1.1486480425226826 1.1486480425226826 1.1486480425226826" />
         </geometry>
         <material name="white" />
      </visual>
   </link>
   <joint type="fixed" name="lunate2pisiform_fixed_left">
      <parent link="lunate_left" />
      <child link="pisiform_left" />
      <origin xyz="0.015378099993293676 -0.011355534548379242 -0.012167628714442777" rpy="0.0 0.0 0.0" />
   </joint>
   <link name="triquetrum_left">
      <inertial>
         <origin xyz="0.0 0.0 0.0" rpy="0.0 0.0 0.0" />
         <mass value="0.02" />
         <inertia ixx="0.0001" iyy="0.0001" izz="0.0001" ixy="0" ixz="0" iyz="0" />
      </inertial>
      <visual name="triquetrum_left">
         <origin xyz="-6.812391269168244e-07 -1.2894266454462067e-06 -3.89797062799388e-06" rpy="1.9269139677822995 0.29745876180457564 0.5516387254770375" />
         <geometry>
            <mesh filename="file:///home/haochen/catkin_ws/src/relaxed_ik_ros1/relaxed_ik_core/configs/urdfs/meshes/triquetrum_left.stl" scale="1.1486480425226826 1.1486480425226826 1.1486480425226826" />
         </geometry>
         <material name="white" />
      </visual>
   </link>
   <joint type="fixed" name="lunate2triquetrum_fixed_left">
      <parent link="lunate_left" />
      <child link="triquetrum_left" />
      <origin xyz="0.01238702049056461 -0.008613711670877596 -0.001480607326811738" rpy="0.0 0.0 0.0" />
   </joint>
   <link name="capitate_left">
      <inertial>
         <origin xyz="-2.499752937609387e-06 -4.319736123192808e-06 1.3404175140865199e-06" rpy="1.2103081004613072 0.2920747955988765 0.020398215496376215" />
         <mass value="0.001912230829037991" />
         <inertia ixx="0.0001" iyy="0.0001" izz="0.0001" ixy="0" ixz="0" iyz="0" />
      </inertial>
      <visual name="capitate_left">
         <origin xyz="-2.871336318575196e-06 -4.96185644212159e-06 1.5396679537184321e-06" rpy="1.2103081004613072 0.29207479559887606 0.02039821549637577" />
         <geometry>
            <mesh filename="file:///home/haochen/catkin_ws/src/relaxed_ik_ros1/relaxed_ik_core/configs/urdfs/meshes/capitate_left.stl" scale="1.1486480425226826 1.1486480425226826 1.1486480425226826" />
         </geometry>
         <material name="white" />
      </visual>
   </link>
   <joint type="fixed" name="lunate2capitate_fixed_left">
      <parent link="lunate_left" />
      <child link="capitate_left" />
      <origin xyz="-0.004585402985750549 -0.017291747632136464 0.0026729039949502827" rpy="0.0 0.0 0.0" />
   </joint>
   <link name="trapezium_left">
      <inertial>
         <origin xyz="0.0 0.0 0.0" rpy="0.0 0.0 0.0" />
         <mass value="0.02" />
         <inertia ixx="0.0001" iyy="0.0001" izz="0.0001" ixy="0" ixz="0" iyz="0" />
      </inertial>
      <visual name="trapezium_left">
         <origin xyz="6.5241929608980676e-06 1.754874978953519e-06 -8.42987886717772e-07" rpy="-0.25650854392346245 0.8000548292338778 -2.2561533548010573" />
         <geometry>
            <mesh filename="file:///home/haochen/catkin_ws/src/relaxed_ik_ros1/relaxed_ik_core/configs/urdfs/meshes/trapezium_left.stl" scale="1.1486480425226826 1.1486480425226826 1.1486480425226826" />
         </geometry>
         <material name="white" />
      </visual>
   </link>
   <joint type="fixed" name="capitate2trapezium_fixed_left">
      <parent link="capitate_left" />
      <child link="trapezium_left" />
      <origin xyz="-0.017566274514299384 -0.005248172906286139 -0.01184026402232381" rpy="0.0 0.0 0.0" />
   </joint>
   <link name="firstmc_left">
      <inertial>
         <origin xyz="-0.013099680893881645 -0.006874528260996441 -0.009698928892781549" rpy="-2.1572247499833637 0.315602977570725 1.7510692763715636" />
         <mass value="0.016" />
         <inertia ixx="0.0001" iyy="0.0001" izz="0.0001" ixy="0" ixz="0" iyz="0" />
      </inertial>
      <visual name="1mc_left">
         <origin xyz="-0.0160228868606346 -0.008320923932854857 -0.010080336290005914" rpy="-2.237451597882739 0.5181491466513539 1.6277365169800726" />
         <geometry>
            <mesh filename="file:///home/haochen/catkin_ws/src/relaxed_ik_ros1/relaxed_ik_core/configs/urdfs/meshes/1mc_left.stl" scale="1.1486480425226826 1.1486480425226826 1.1486480425226826" />
         </geometry>
         <material name="white" />
      </visual>
   </link>
   <link name="cmc_abduction_dummy_left">
      <inertial>
         <origin xyz="-1.734723475976807e-17 -1.0408340855860843e-17 -8.673617379884035e-19" rpy="-0.7286789533902662 -0.04241170412851947 0.01617642349516335" />
         <mass value="0.001" />
         <inertia ixx="1e-09" iyy="1e-09" izz="1e-09" ixy="0" ixz="0" iyz="0" />
      </inertial>
   </link>
   <joint type="revolute" name="cmc_abduction_left">
      <parent link="trapezium_left" />
      <child link="cmc_abduction_dummy_left" />
      <origin xyz="-0.008270265906163317 -0.006202699429622488 -0.002871620106306705" rpy="0.7286789533902661 0.04241170412851947 0.01617642349516324" />
      <axis xyz="1.747988441681546e-18 -1.0772761261336016e-16 -1.0" />
      <limit lower="-0.5" upper="0.78" effort="100" velocity="100" />
   </joint>
   <joint type="revolute" name="cmc_flexion_left">
      <parent link="cmc_abduction_dummy_left" />
      <child link="firstmc_left" />
      <origin xyz="-6.938893903907228e-18 -6.938893903907228e-18 1.214306433183765e-17" rpy="-1.7353556432102097 -0.24272282231633158 0.5745472836968706" />
      <axis xyz="-2.8391311673900116e-17 -5.045193471461809e-17 -1.0000000000000002" />
      <limit lower="-0.78" upper="0.7" effort="100" velocity="100" />
   </joint>
   <link name="proximal_thumb_left">
      <inertial>
         <origin xyz="-0.009175945436263391 -0.017323667062881902 -0.0036376620025967907" rpy="2.1934671196508537 -0.3312682727761356 -1.3835402268256396" />
         <mass value="0.0079" />
         <inertia ixx="0.0001" iyy="0.0001" izz="0.0001" ixy="0" ixz="0" iyz="0" />
      </inertial>
      <visual name="thumbprox_left">
         <origin xyz="-0.00938848705426134 -0.018360028550254544 -0.003604674286245696" rpy="1.7513489423197717 0.12389205032924067 -0.43579123948592813" />
         <geometry>
            <mesh filename="file:///home/haochen/catkin_ws/src/relaxed_ik_ros1/relaxed_ik_core/configs/urdfs/meshes/thumbprox_left.stl" scale="1.1486480425226826 1.1486480425226826 1.1486480425226826" />
         </geometry>
         <material name="white" />
      </visual>
   </link>
   <joint type="revolute" name="mp_flexion_left">
      <parent link="firstmc_left" />
      <child link="proximal_thumb_left" />
      <origin xyz="-0.031296392286403026 -0.015313902373446445 -0.021977175552854895" rpy="1.252742510164709 0.5549106329448805 0.3775526480844189" />
      <axis xyz="-7.360873981229693e-17 -1.0205699454745994e-16 -1.0000000000000002" />
      <limit lower="-0.785398" upper="0.698132" effort="100" velocity="100" />
   </joint>
   <link name="distal_thumb_left">
      <inertial>
         <origin xyz="-0.005505270898240551 -0.01130683517570466 0.0008529188979227928" rpy="1.5541483151428697 0.6236827888860805 -0.41877836332372254" />
         <mass value="0.003" />
         <inertia ixx="0.0001" iyy="0.0001" izz="0.0001" ixy="0" ixz="0" iyz="0" />
      </inertial>
      <visual name="thumbdist_left">
         <origin xyz="-0.004781948198670019 -0.011211845491539876 0.0011139682916029292" rpy="1.5220799311772146 0.03178831257590442 -0.4785542231651295" />
         <geometry>
            <mesh filename="file:///home/haochen/catkin_ws/src/relaxed_ik_ros1/relaxed_ik_core/configs/urdfs/meshes/thumbdist_left.stl" scale="1.1486480425226826 1.1486480425226826 1.1486480425226826" />
         </geometry>
         <material name="white" />
      </visual>
   </link>
   <joint type="revolute" name="ip_flexion_left">
      <parent link="proximal_thumb_left" />
      <child link="distal_thumb_left" />
      <origin xyz="-0.01530361676331593 -0.03162676148079482 -0.0066182282430972406" rpy="0.29479434175333596 -0.03270997999703473 0.011022901491355958" />
      <axis xyz="-1.923774407218676e-17 -2.7135002682840594e-16 -1.0000000000000009" />
      <limit lower="-1.309" upper="0.436332" effort="100" velocity="100" />
   </joint>
   <link name="trapezoid_left">
      <inertial>
         <origin xyz="0.0 0.0 0.0" rpy="0.0 0.0 0.0" />
         <mass value="0.02" />
         <inertia ixx="0.0001" iyy="0.0001" izz="0.0001" ixy="0" ixz="0" iyz="0" />
      </inertial>
      <visual name="trapezoid_left">
         <origin xyz="-1.578099308839273e-06 -1.6966149991061441e-06 2.172476089336295e-07" rpy="0.27598761251820686 -0.5558008487263413 -0.19209924739735607" />
         <geometry>
            <mesh filename="file:///home/haochen/catkin_ws/src/relaxed_ik_ros1/relaxed_ik_core/configs/urdfs/meshes/trapezoid_left.stl" scale="1.1486480425226826 1.1486480425226826 1.1486480425226826" />
         </geometry>
         <material name="white" />
      </visual>
   </link>
   <joint type="fixed" name="capitate2trapezoid_fixed_left">
      <parent link="capitate_left" />
      <child link="trapezoid_left" />
      <origin xyz="-0.010502089052784887 -0.004665808348727138 -0.00283026877677589" rpy="0.0 0.0 0.0" />
   </joint>
   <link name="hamate_left">
      <inertial>
         <origin xyz="0.0 0.0 0.0" rpy="0.0 0.0 0.0" />
         <mass value="0.02" />
         <inertia ixx="0.0001" iyy="0.0001" izz="0.0001" ixy="0" ixz="0" iyz="0" />
      </inertial>
      <visual name="hamate_left">
         <origin xyz="1.3189802766651153e-05 -1.5780058425706942e-06 1.7467973266911685e-06" rpy="1.9411415415940314 0.45538466433185576 0.6664160632978575" />
         <geometry>
            <mesh filename="file:///home/haochen/catkin_ws/src/relaxed_ik_ros1/relaxed_ik_core/configs/urdfs/meshes/hamate_left.stl" scale="1.1486480425226826 1.1486480425226826 1.1486480425226826" />
         </geometry>
         <material name="white" />
      </visual>
   </link>
   <joint type="fixed" name="capitate2hamate_fixed_left">
      <parent link="capitate_left" />
      <child link="hamate_left" />
      <origin xyz="0.012599520378431307 -0.002865876866094092 -0.0008614860318920119" rpy="0.0 0.0 0.0" />
   </joint>
   <link name="secondmc_left">
      <inertial>
         <origin xyz="0.0 0.0 0.0" rpy="0.0 0.0 0.0" />
         <mass value="0.02" />
         <inertia ixx="0.0001" iyy="0.0001" izz="0.0001" ixy="0" ixz="0" iyz="0" />
      </inertial>
      <visual name="2mc_left">
         <origin xyz="0.00012040663444485428 0.00014517430010183366 -0.00016062127327075987" rpy="-1.228861140749632 1.0576482637579705 -2.995769549013369" />
         <geometry>
            <mesh filename="file:///home/haochen/catkin_ws/src/relaxed_ik_ros1/relaxed_ik_core/configs/urdfs/meshes/2mc_left.stl" scale="1.1486480425226826 1.1486480425226826 1.1486480425226826" />
         </geometry>
         <material name="white" />
      </visual>
   </link>
   <joint type="fixed" name="capitate2secondmc_fixed_left">
      <parent link="capitate_left" />
      <child link="secondmc_left" />
      <origin xyz="-0.016867896504445593 -0.04321213935970332 0.00577999694997414" rpy="0.0 0.0 0.0" />
   </joint>
   <link name="proxph2_left">
      <inertial>
         <origin xyz="-1.734723475976807e-18 0.0 4.336808689942018e-19" rpy="0.0861356540103359 -0.05502674551362019 -0.002371946121602242" />
         <mass value="0.01" />
         <inertia ixx="0.0001" iyy="0.0001" izz="0.0001" ixy="0" ixz="0" iyz="0" />
      </inertial>
      <visual name="2proxph_left">
         <origin xyz="-0.005137544136697508 -0.026105067500285923 0.002848587030533962" rpy="1.32310707032668 1.2754347723112271 -0.40864446039367786" />
         <geometry>
            <mesh filename="file:///home/haochen/catkin_ws/src/relaxed_ik_ros1/relaxed_ik_core/configs/urdfs/meshes/2proxph_left.stl" scale="1.1486480425226826 1.1486480425226826 1.1486480425226826" />
         </geometry>
         <material name="white" />
      </visual>
   </link>
   <link name="mcp2_flexion_dummy_left">
      <inertial>
         <origin xyz="3.469446951953614e-18 2.7755575615628914e-17 3.469446951953614e-18" rpy="1.5707963267948961 1.4708802086674053 1.4708802086674049" />
         <mass value="0.001" />
         <inertia ixx="1e-09" iyy="1e-09" izz="1e-09" ixy="0" ixz="0" iyz="0" />
      </inertial>
   </link>
   <joint type="revolute" name="mcp2_flexion_left">
      <parent link="secondmc_left" />
      <child link="mcp2_flexion_dummy_left" />
      <origin xyz="-0.004021416796871912 -0.032441266664968126 0.004158105913932111" rpy="-1.5707963267948977 -1.4708802086674053 1.4708802086674064" />
      <axis xyz="-5.2438525824824176e-20 7.039945989835385e-18 -1.0" />
      <limit lower="0.0" upper="1.5708" effort="100" velocity="100" />
   </joint>
   <joint type="revolute" name="mcp2_abduction_left">
      <parent link="mcp2_flexion_dummy_left" />
      <child link="proxph2_left" />
      <origin xyz="6.938893903907228e-18 2.7755575615628914e-17 5.204170427930421e-18" rpy="1.996706135703523 1.4588445662369582 1.9856122470713673" />
      <axis xyz="-2.8382323702885056e-16 2.4019512150402412e-17 -0.9999999999999999" />
      <limit lower="-0.261799" upper="0.261799" effort="100" velocity="100" />
   </joint>
   <link name="midph2_left">
      <inertial>
         <origin xyz="-6.938893903907228e-18 -8.326672684688674e-17 -3.642919299551295e-17" rpy="2.6739267894988212 1.3474886382146267 2.5617140966854453" />
         <mass value="0.003" />
         <inertia ixx="0.0001" iyy="0.0001" izz="0.0001" ixy="0" ixz="0" iyz="0" />
      </inertial>
      <visual name="2midph_left">
         <origin xyz="-0.0010981405744331756 -0.01573108276866697 0.00028629955433523424" rpy="-1.5630400763369499 0.0019507371444629218 3.1305336815451996" />
         <geometry>
            <mesh filename="file:///home/haochen/catkin_ws/src/relaxed_ik_ros1/relaxed_ik_core/configs/urdfs/meshes/2midph_left.stl" scale="1.1486480425226826 1.1486480425226826 1.1486480425226826" />
         </geometry>
         <material name="white" />
      </visual>
   </link>
   <joint type="revolute" name="pm2_flexion_left">
      <parent link="proxph2_left" />
      <child link="midph2_left" />
      <origin xyz="-0.00896380272452799 -0.04793519890568425 0.0038243567913669348" rpy="-3.1093030719372425 -1.326545003064804 2.985625911527994" />
      <axis xyz="-6.004321121326396e-16 -1.7684176337434925e-16 -0.9999999999999996" />
      <limit lower="0.0" upper="1.5708" effort="100" velocity="100" />
   </joint>
   <link name="distph2_left">
      <inertial>
         <origin xyz="-1.3877787807814457e-17 2.7755575615628914e-17 0.0" rpy="1.5707963267948983 1.4707963268582902 1.4707963268582915" />
         <mass value="0.002" />
         <inertia ixx="0.0001" iyy="0.0001" izz="0.0001" ixy="0" ixz="0" iyz="0" />
      </inertial>
      <visual name="2distph_left">
         <origin xyz="-0.0006399561752213206 -0.009820984182418249 0.00024663832046598055" rpy="-1.5239710771919284 0.03676633885392744 3.140805196244449" />
         <geometry>
            <mesh filename="file:///home/haochen/catkin_ws/src/relaxed_ik_ros1/relaxed_ik_core/configs/urdfs/meshes/2distph_left.stl" scale="1.1486480425226826 1.1486480425226826 1.1486480425226826" />
         </geometry>
         <material name="white" />
      </visual>
   </link>
   <joint type="revolute" name="md2_flexion_left">
      <parent link="midph2_left" />
      <child link="distph2_left" />
      <origin xyz="-0.0013930466537968242 -0.028836877205181244 0.0006023764869396448" rpy="0.022138329695812073 0.19777869365516998 -2.5098334244374673e-05" />
      <axis xyz="-2.4455606779405633e-18 -4.090344666757575e-17 -0.9999999999999998" />
      <limit lower="0.0" upper="1.5708" effort="100" velocity="100" />
   </joint>
   <link name="thirdmc_left">
      <inertial>
         <origin xyz="0.0 0.0 0.0" rpy="0.0 0.0 0.0" />
         <mass value="0.02" />
         <inertia ixx="0.0001" iyy="0.0001" izz="0.0001" ixy="0" ixz="0" iyz="0" />
      </inertial>
      <visual name="3mc_left">
         <origin xyz="-1.4041991268940422e-05 0.0005937060068091811 -0.0002766064189725845" rpy="1.4450266262998412 -0.18035841028182698 0.007490416792627297" />
         <geometry>
            <mesh filename="file:///home/haochen/catkin_ws/src/relaxed_ik_ros1/relaxed_ik_core/configs/urdfs/meshes/3mc_left.stl" scale="1.1486480425226826 1.1486480425226826 1.1486480425226826" />
         </geometry>
         <material name="white" />
      </visual>
   </link>
   <joint type="fixed" name="capitate2thirdmc_fixed_left">
      <parent link="capitate_left" />
      <child link="thirdmc_left" />
      <origin xyz="-0.0005479051162833194 -0.045071800540547546 0.00847357660968983" rpy="0.0 0.0 0.0" />
   </joint>
   <link name="proxph3_left">
      <inertial>
         <origin xyz="0.0 1.3877787807814457e-17 -1.734723475976807e-18" rpy="0.0 -0.19999959192895989 0.0" />
         <mass value="0.01" />
         <inertia ixx="0.0001" iyy="0.0001" izz="0.0001" ixy="0" ixz="0" iyz="0" />
      </inertial>
      <visual name="3proxph_left">
         <origin xyz="-0.0022376730345372714 -0.026750169029813788 0.004832152397514248" rpy="1.1265372608123134 1.2987544122063608 -0.46937964805067295" />
         <geometry>
            <mesh filename="file:///home/haochen/catkin_ws/src/relaxed_ik_ros1/relaxed_ik_core/configs/urdfs/meshes/3proxph_left.stl" scale="1.1486480425226826 1.1486480425226826 1.1486480425226826" />
         </geometry>
         <material name="white" />
      </visual>
   </link>
   <link name="mcp3_flexion_dummy_left">
      <inertial>
         <origin xyz="4.336808689942018e-19 0.0 0.0" rpy="0.0 1.370796734865936 0.0" />
         <mass value="0.001" />
         <inertia ixx="1e-09" iyy="1e-09" izz="1e-09" ixy="0" ixz="0" iyz="0" />
      </inertial>
   </link>
   <joint type="revolute" name="mcp3_flexion_left">
      <parent link="thirdmc_left" />
      <child link="mcp3_flexion_dummy_left" />
      <origin xyz="-0.0002756755302054433 -0.03019795703792133 0.00204229621960533" rpy="0.0 -1.370796734865936 0.0" />
      <axis xyz="1.842288986358278e-17 0.0 -1.0" />
      <limit lower="0.0" upper="1.5708" effort="100" velocity="100" />
   </joint>
   <joint type="revolute" name="mcp3_abduction_left">
      <parent link="mcp3_flexion_dummy_left" />
      <child link="proxph3_left" />
      <origin xyz="3.2526065174565133e-19 -1.3877787807814457e-17 0.0" rpy="-0.0 1.5707963267948961 0.0" />
      <axis xyz="-4.59135596783022e-18 0.0 -1.0" />
      <limit lower="-0.261799" upper="0.261799" effort="100" velocity="100" />
   </joint>
   <link name="midph3_left">
      <inertial>
         <origin xyz="0.0 0.0 0.0" rpy="0.0 0.0 0.0" />
         <mass value="0.002" />
         <inertia ixx="0.0001" iyy="0.0001" izz="0.0001" ixy="0" ixz="0" iyz="0" />
      </inertial>
      <visual name="3midph_left">
         <origin xyz="-0.0007829275525715051 -0.017087217488224296 0.0018236916944641152" rpy="-0.7901456653983319 1.4979259934357856 -2.4117147631811813" />
         <geometry>
            <mesh filename="file:///home/haochen/catkin_ws/src/relaxed_ik_ros1/relaxed_ik_core/configs/urdfs/meshes/3midph_left.stl" scale="1.1486480425226826 1.1486480425226826 1.1486480425226826" />
         </geometry>
         <material name="white" />
      </visual>
   </link>
   <joint type="revolute" name="pm3_flexion_left">
      <parent link="proxph3_left" />
      <child link="midph3_left" />
      <origin xyz="-0.0032791804486541187 -0.050782878607970316 0.006636901655556221" rpy="0.0 -0.19999959192895989 0.0" />
      <axis xyz="0.9999999999999999 0.0 -1.1075375161486551e-18" />
      <limit lower="0.0" upper="1.5708" effort="100" velocity="100" />
   </joint>
   <link name="distph3_left">
      <inertial>
         <origin xyz="0.0 0.0 0.0" rpy="0.0 0.0 0.0" />
         <mass value="0.002" />
         <inertia ixx="0.0001" iyy="0.0001" izz="0.0001" ixy="0" ixz="0" iyz="0" />
      </inertial>
      <visual name="3distph_left">
         <origin xyz="-0.0007206053092270459 -0.00983115067815017 -3.730927176512182e-05" rpy="0.4079397820603101 1.4851549016387628 -1.2108481043436292" />
         <geometry>
            <mesh filename="file:///home/haochen/catkin_ws/src/relaxed_ik_ros1/relaxed_ik_core/configs/urdfs/meshes/3distph_left.stl" scale="1.1486480425226826 1.1486480425226826 1.1486480425226826" />
         </geometry>
         <material name="white" />
      </visual>
   </link>
   <joint type="revolute" name="md3_flexion_left">
      <parent link="midph3_left" />
      <child link="distph3_left" />
      <origin xyz="-0.0015679045780434622 -0.033364779691156365 0.0022444582750893206" rpy="0.0 0.0 0.0" />
      <axis xyz="0.9999999999999999 0.0 -1.1075375161486551e-18" />
      <limit lower="0.0" upper="1.5708" effort="100" velocity="100" />
   </joint>
   <link name="fourthmc_left">
      <inertial>
         <origin xyz="0.0 0.0 0.0" rpy="0.0 0.0 0.0" />
         <mass value="0.02" />
         <inertia ixx="0.0001" iyy="0.0001" izz="0.0001" ixy="0" ixz="0" iyz="0" />
      </inertial>
      <visual name="4mc_left">
         <origin xyz="-5.0312314088996404e-05 0.0006110152739212549 -0.00019155796598172709" rpy="1.5268660941250807 0.3772702504935901 0.07031755099911197" />
         <geometry>
            <mesh filename="file:///home/haochen/catkin_ws/src/relaxed_ik_ros1/relaxed_ik_core/configs/urdfs/meshes/4mc_left.stl" scale="1.1486480425226826 1.1486480425226826 1.1486480425226826" />
         </geometry>
         <material name="white" />
      </visual>
   </link>
   <joint type="fixed" name="capitate2fourthmc_fixed_left">
      <parent link="capitate_left" />
      <child link="fourthmc_left" />
      <origin xyz="0.013836614320228233 -0.04654207003497658 0.004035200573382184" rpy="0.0 0.0 0.0" />
   </joint>
   <link name="proxph4_left">
      <inertial>
         <origin xyz="-1.734723475976807e-18 1.3877787807814457e-17 -2.6020852139652106e-18" rpy="0.0 -0.4500004640280284 0.0" />
         <mass value="0.01" />
         <inertia ixx="0.0001" iyy="0.0001" izz="0.0001" ixy="0" ixz="0" iyz="0" />
      </inertial>
      <visual name="4proxph_left">
         <origin xyz="0.0015305635334287304 -0.024801556345655472 0.0024381744741931496" rpy="0.6976319582938992 1.4758909364414672 -0.7976662974326221" />
         <geometry>
            <mesh filename="file:///home/haochen/catkin_ws/src/relaxed_ik_ros1/relaxed_ik_core/configs/urdfs/meshes/4proxph_left.stl" scale="1.1486480425226826 1.1486480425226826 1.1486480425226826" />
         </geometry>
         <material name="white" />
      </visual>
   </link>
   <link name="mcp4_flexion_dummy_left">
      <inertial>
         <origin xyz="1.734723475976807e-18 0.0 8.673617379884035e-19" rpy="0.0 1.120795862766868 0.0" />
         <mass value="0.001" />
         <inertia ixx="1e-09" iyy="1e-09" izz="1e-09" ixy="0" ixz="0" iyz="0" />
      </inertial>
   </link>
   <joint type="revolute" name="mcp4_flexion_left">
      <parent link="fourthmc_left" />
      <child link="mcp4_flexion_dummy_left" />
      <origin xyz="0.002102025917816509 -0.02721032347931983 -0.0001987161113564239" rpy="0.0 -1.1207958627668684 0.0" />
      <axis xyz="-7.907580905939781e-17 0.0 -1.0" />
      <limit lower="0.0" upper="1.5708" effort="100" velocity="100" />
   </joint>
   <joint type="revolute" name="mcp4_abduction_left">
      <parent link="mcp4_flexion_dummy_left" />
      <child link="proxph4_left" />
      <origin xyz="3.469446951953614e-18 -1.3877787807814457e-17 1.6263032587282567e-19" rpy="-0.0 1.5707963267948961 0.0" />
      <axis xyz="4.994681042330142e-17 0.0 -1.0000000000000002" />
      <limit lower="-0.261799" upper="0.261799" effort="100" velocity="100" />
   </joint>
   <link name="midph4_left">
      <inertial>
         <origin xyz="0.0 2.7755575615628914e-17 1.734723475976807e-18" rpy="-5.8096713723763484e-33 1.1707966444174693 -6.285106853470097e-33" />
         <mass value="0.003" />
         <inertia ixx="0.0001" iyy="0.0001" izz="0.0001" ixy="0" ixz="0" iyz="0" />
      </inertial>
      <visual name="4midph_left">
         <origin xyz="0.0013530880889787793 -0.015064657847648752 -0.0014358467691289734" rpy="-1.624420311140701 0.00529879897844765 -3.0977891945924623" />
         <geometry>
            <mesh filename="file:///home/haochen/catkin_ws/src/relaxed_ik_ros1/relaxed_ik_core/configs/urdfs/meshes/4midph_left.stl" scale="1.1486480425226826 1.1486480425226826 1.1486480425226826" />
         </geometry>
         <material name="white" />
      </visual>
   </link>
   <joint type="revolute" name="pm4_flexion_left">
      <parent link="proxph4_left" />
      <child link="midph4_left" />
      <origin xyz="0.0029770056462484693 -0.04623882695175058 0.003153798086735826" rpy="-3.141592653589793 -1.5207955451442956 -3.141592653589793" />
      <axis xyz="-1.228163387906391e-16 -2.5729218551481257e-33 -1.0000000000000002" />
      <limit lower="0.0" upper="1.5708" effort="100" velocity="100" />
   </joint>
   <link name="distph4_left">
      <inertial>
         <origin xyz="-3.469446951953614e-18 2.7755575615628914e-17 7.589415207398531e-18" rpy="9.507900496666728e-34 0.9707969349430008 -3.875608070853002e-33" />
         <mass value="0.002" />
         <inertia ixx="0.0001" iyy="0.0001" izz="0.0001" ixy="0" ixz="0" iyz="0" />
      </inertial>
      <visual name="4distph_left">
         <origin xyz="0.0014195100813310085 -0.010166091201686198 6.590653983945538e-05" rpy="-1.5832780312239771 0.030396363417948935 -2.9652765496152345" />
         <geometry>
            <mesh filename="file:///home/haochen/catkin_ws/src/relaxed_ik_ros1/relaxed_ik_core/configs/urdfs/meshes/4distph_left.stl" scale="1.1486480425226826 1.1486480425226826 1.1486480425226826" />
         </geometry>
         <material name="white" />
      </visual>
   </link>
   <joint type="revolute" name="md4_flexion_left">
      <parent link="midph4_left" />
      <child link="distph4_left" />
      <origin xyz="0.0016320439711825516 -0.028473836326094792 -0.002199495880604859" rpy="-4.462365316954919e-33 0.19999970947446855 -1.3781457552156878e-33" />
      <axis xyz="-5.254894459090136e-16 -3.28052241842023e-33 -1.0000000000000007" />
      <limit lower="0.0" upper="1.5708" effort="100" velocity="100" />
   </joint>
   <link name="fifthmc_left">
      <inertial>
         <origin xyz="0.0 0.0 0.0" rpy="0.0 0.0 0.0" />
         <mass value="0.02" />
         <inertia ixx="0.0001" iyy="0.0001" izz="0.0001" ixy="0" ixz="0" iyz="0" />
      </inertial>
      <visual name="5mc_left">
         <origin xyz="-0.00022361373693417091 0.00048072589841006833 -0.00014777245296331704" rpy="1.6537260233892073 1.161764483067726 0.20407074680325366" />
         <geometry>
            <mesh filename="file:///home/haochen/catkin_ws/src/relaxed_ik_ros1/relaxed_ik_core/configs/urdfs/meshes/5mc_left.stl" scale="1.1486480425226826 1.1486480425226826 1.1486480425226826" />
         </geometry>
         <material name="white" />
      </visual>
   </link>
   <joint type="fixed" name="capitate2fifthmc_fixed_left">
      <parent link="capitate_left" />
      <child link="fifthmc_left" />
      <origin xyz="0.025150797539076657 -0.0398385600588142 -0.004844997443360676" rpy="0.0 0.0 0.0" />
   </joint>
   <link name="proxph5_left">
      <inertial>
         <origin xyz="-3.469446951953614e-18 0.0 -5.204170427930421e-18" rpy="0.0 -0.599999391851897 0.0" />
         <mass value="0.005" />
         <inertia ixx="0.0001" iyy="0.0001" izz="0.0001" ixy="0" ixz="0" iyz="0" />
      </inertial>
      <visual name="5proxph_left">
         <origin xyz="0.003908473121372408 -0.022193606020726647 0.0010123208496313324" rpy="-1.4569822139036388 1.3815149067226087 -2.8851965671744555" />
         <geometry>
            <mesh filename="file:///home/haochen/catkin_ws/src/relaxed_ik_ros1/relaxed_ik_core/configs/urdfs/meshes/5proxph_left.stl" scale="1.1486480425226826 1.1486480425226826 1.1486480425226826" />
         </geometry>
         <material name="white" />
      </visual>
   </link>
   <link name="mcp5_flexion_dummy_left">
      <inertial>
         <origin xyz="-3.469446951953614e-18 1.3877787807814457e-17 -2.6020852139652106e-18" rpy="0.0 0.9707969349430003 0.0" />
         <mass value="0.001" />
         <inertia ixx="1e-09" iyy="1e-09" izz="1e-09" ixy="0" ixz="0" iyz="0" />
      </inertial>
   </link>
   <joint type="revolute" name="mcp5_flexion_left">
      <parent link="fifthmc_left" />
      <child link="mcp5_flexion_dummy_left" />
      <origin xyz="0.0018343909239087238 -0.024616676199303605 -0.0017183774716139338" rpy="0.0 -0.9707969349430003 0.0" />
      <axis xyz="2.7011479700438378e-17 0.0 -1.0" />
      <limit lower="0.0" upper="1.5708" effort="100" velocity="100" />
   </joint>
   <joint type="revolute" name="mcp5_abduction_left">
      <parent link="mcp5_flexion_dummy_left" />
      <child link="proxph5_left" />
      <origin xyz="3.469446951953614e-18 0.0 -1.734723475976807e-18" rpy="-0.0 1.5707963267948966 0.0" />
      <axis xyz="1.804436795852415e-16 0.0 -1.0000000000000002" />
      <limit lower="-0.261799" upper="0.261799" effort="100" velocity="100" />
   </joint>
   <link name="midph5_left">
      <inertial>
         <origin xyz="-6.938893903907228e-18 1.3877787807814457e-17 -1.734723475976807e-18" rpy="0.0 0.9707969349430003 0.0" />
         <mass value="0.002" />
         <inertia ixx="0.0001" iyy="0.0001" izz="0.0001" ixy="0" ixz="0" iyz="0" />
      </inertial>
      <visual name="5midph_left">
         <origin xyz="-0.00022080340054864101 -0.013520259378114997 -0.0023992904475566568" rpy="-1.7327462170365329 -0.1431630889135289 -3.08764894477981" />
         <geometry>
            <mesh filename="file:///home/haochen/catkin_ws/src/relaxed_ik_ros1/relaxed_ik_core/configs/urdfs/meshes/5midph_left.stl" scale="1.1486480425226826 1.1486480425226826 1.1486480425226826" />
         </geometry>
         <material name="white" />
      </visual>
   </link>
   <joint type="revolute" name="pm5_flexion_left">
      <parent link="proxph5_left" />
      <child link="midph5_left" />
      <origin xyz="0.006871847516719935 -0.04084937033623416 0.0006944757577670244" rpy="0.0 -1.5707963267948961 0.0" />
      <axis xyz="1.019142349991081e-16 0.0 -1.0000000000000004" />
      <limit lower="0.0" upper="1.5708" effort="100" velocity="100" />
   </joint>
   <link name="distph5_left">
      <inertial>
         <origin xyz="1.0408340855860843e-17 0.0 5.204170427930421e-18" rpy="-0.30068756862856233 0.6985554313998295 -0.11023436132302195" />
         <mass value="0.001" />
         <inertia ixx="0.0001" iyy="0.0001" izz="0.0001" ixy="0" ixz="0" iyz="0" />
      </inertial>
      <visual name="5distph_left">
         <origin xyz="0.001165229380542688 -0.009049505681676562 0.0005139558880464246" rpy="-1.5131584280044281 0.07399081576380362 -2.9725845702930727" />
         <geometry>
            <mesh filename="file:///home/haochen/catkin_ws/src/relaxed_ik_ros1/relaxed_ik_core/configs/urdfs/meshes/5distph_left.stl" scale="1.1486480425226826 1.1486480425226826 1.1486480425226826" />
         </geometry>
         <material name="white" />
      </visual>
   </link>
   <joint type="revolute" name="md5_flexion_left">
      <parent link="midph5_left" />
      <child link="distph5_left" />
      <origin xyz="-0.000264351531066514 -0.023750595575241493 -0.004176520440067239" rpy="0.20638367854381948 0.2682608800927275 -0.08747994233519726" />
      <axis xyz="-3.067053893791756e-16 3.6436868920186926e-17 -1.0000000000000002" />
      <limit lower="0.0" upper="1.5708" effort="100" velocity="100" />
   </joint>
   <link name="THtip_left">
      <inertial>
         <origin xyz="-1.3877787807814457e-17 0.0 0.0" rpy="-8.981636647091639e-18 0.0 9.901469019638499e-18" />
         <mass value="0.001" />
         <inertia ixx="1e-09" iyy="1e-09" izz="1e-09" ixy="0" ixz="0" iyz="0" />
      </inertial>
   </link>
   <joint type="fixed" name="THtip_joint_left">
      <parent link="distal_thumb_left" />
      <child link="THtip_left" />
      <origin xyz="-0.011304973256230644 -0.02471051649524722 0.0023927444174953946" rpy="-0.5009125402511723 -0.05012299056598346 0.012825373716091937" />
   </joint>
   <link name="IFtip_left">
      <inertial>
         <origin xyz="-3.469446951953614e-18 0.0 0.0" rpy="1.9842975991750576e-18 0.0 -4.128063011068848e-20" />
         <mass value="0.001" />
         <inertia ixx="1e-09" iyy="1e-09" izz="1e-09" ixy="0" ixz="0" iyz="0" />
      </inertial>
   </link>
   <joint type="fixed" name="IFtip_joint_left">
      <parent link="distph2_left" />
      <child link="IFtip_left" />
      <origin xyz="-0.002076706726373289 -0.020697797526362027 0.00022169691984058083" rpy="1.5707963267948983 1.4707963268582902 1.4707963268582915" />
   </joint>
   <link name="MFtip_left">
      <inertial>
         <origin xyz="0.0 0.0 0.0" rpy="0.0 0.0 0.0" />
         <mass value="0.001" />
         <inertia ixx="1e-09" iyy="1e-09" izz="1e-09" ixy="0" ixz="0" iyz="0" />
      </inertial>
   </link>
   <joint type="fixed" name="MFtip_joint_left">
      <parent link="distph3_left" />
      <child link="MFtip_left" />
      <origin xyz="-0.0022972960850453656 -0.021824312807930957 -0.001148648042522682" rpy="0.0 0.0 0.0" />
   </joint>
   <link name="RFtip_left">
      <inertial>
         <origin xyz="0.0 0.0 0.0" rpy="0.0 0.0 1.7105694144590052e-49" />
         <mass value="0.001" />
         <inertia ixx="1e-09" iyy="1e-09" izz="1e-09" ixy="0" ixz="0" iyz="0" />
      </inertial>
   </link>
   <joint type="fixed" name="RFtip_joint_left">
      <parent link="distph4_left" />
      <child link="RFtip_left" />
      <origin xyz="0.0015965954281736243 -0.020675664765408275 -0.0002994456376664131" rpy="9.507900496666728e-34 0.9707969349430008 -3.875608070853002e-33" />
   </joint>
   <link name="LFtip_left">
      <inertial>
         <origin xyz="0.0 2.7755575615628914e-17 -3.469446951953614e-18" rpy="-2.3461332654756542e-17 0.0 -2.9436483604948474e-18" />
         <mass value="0.001" />
         <inertia ixx="1e-09" iyy="1e-09" izz="1e-09" ixy="0" ixz="0" iyz="0" />
      </inertial>
   </link>
   <joint type="fixed" name="LFtip_joint_left">
      <parent link="distph5_left" />
      <child link="LFtip_left" />
      <origin xyz="0.0003031599163330718 -0.01982519198469429 0.0011696846527624316" rpy="-0.30068756862856233 0.6985554313998295 -0.11023436132302195" />
   </joint>
</robot>