<?xml version="1.0" ?>
<robot name="converted_robot">
   <link name="world">
      <!-- <inertial>
         <origin xyz="0.0 0.0 0.0" rpy="0.0 0.0 0.0"/>
         <mass value="0.0"/>
         <inertia ixx="0.0" iyy="0.0" izz="0.0" ixy="0" ixz="0" iyz="0"/>
      </inertial> -->
   </link>
   <link name="full_body">
      <inertial>
         <origin xyz="0.007615849752048459 0.07753652439376407 0.9316260541842353" rpy="-0.00179963197707933 -0.06338426904227434 -1.5440763828049016"/>
         <mass value="44.9532633117967"/>
         <inertia ixx="9.522683572441872" iyy="9.41713827134163" izz="0.23787107864819027" ixy="0" ixz="0" iyz="0"/>
      </inertial>
      <visual name="body_norighthand">
         <origin xyz="0.007615849752048459 0.07753652439376407 0.9316260541842353" rpy="-0.0017996319770796632 -0.06338426904227434 -1.5440763828049011"/>
         <geometry>
            <mesh filename="file:///home/haochen/catkin_ws/src/relaxed_ik_ros1/relaxed_ik_core/configs/urdfs/meshes/body_norighthand.stl"/>
         </geometry>
         <material name="white"/>
      </visual>
   </link>
   <joint type="fixed" name="world2full_body_fixed">
      <parent link="world"/>
      <child link="full_body"/>
      <origin xyz="0.0 0.0 0.0" rpy="0.0 0.0 0.0"/>
   </joint>
   <link name="thorax">
      <inertial>
         <origin xyz="0.0 0.08 1.4" rpy="1.5707956926584654 -0.0007963265424062449 -1.5699999997475105"/>
         <mass value="0.001"/>
         <inertia ixx="0.0001" iyy="0.0001" izz="0.0001" ixy="0" ixz="0" iyz="0"/>
      </inertial>
   </link>
   <joint type="fixed" name="full_body2thorax_fixed">
      <parent link="full_body"/>
      <child link="thorax"/>
      <origin xyz="0.0 0.08 1.4" rpy="1.5707956926584654 -0.0007963265424062449 -1.5699999997475105"/>
   </joint>
   <link name="clavicle">
      <inertial>
         <origin xyz="-0.011096 0.0063723 0.054168" rpy="-0.07104231589281579 0.3302726301361625 -0.8205592253411178"/>
         <mass value="0.156"/>
         <inertia ixx="0.0002981212467277896" iyy="0.00023064081640291608" izz="0.0001" ixy="0" ixz="0" iyz="0"/>
      </inertial>
   </link>
   <joint type="fixed" name="thorax2clavicle_fixed">
      <parent link="thorax"/>
      <child link="clavicle"/>
      <origin xyz="0.006325 0.00693 0.025465" rpy="0.0 0.0 0.0"/>
   </joint>
   <link name="clavphant">
      <inertial>
         <origin xyz="-0.01433 0.02007 0.135535" rpy="0.0 0.0 0.0"/>
         <mass value="0.001"/>
         <inertia ixx="0.0001" iyy="0.0001" izz="0.0001" ixy="0" ixz="0" iyz="0"/>
      </inertial>
   </link>
   <joint type="fixed" name="clavicle2clavphant_fixed">
      <parent link="clavicle"/>
      <child link="clavphant"/>
      <origin xyz="-0.01433 0.02007 0.135535" rpy="0.0 0.0 0.0"/>
   </joint>
   <link name="scapula">
      <inertial>
         <origin xyz="-0.054694 -0.035032 -0.043734" rpy="1.8557567271253967 -0.6404353237301579 0.6774026029736876"/>
         <mass value="0.70396"/>
         <inertia ixx="0.0012527999999999999" iyy="0.0012527999999999999" izz="0.0012527999999999999" ixy="0" ixz="0" iyz="0"/>
      </inertial>
   </link>
   <joint type="fixed" name="clavphant2scapula_fixed">
      <parent link="clavphant"/>
      <child link="scapula"/>
      <origin xyz="0.0 0.0 0.0" rpy="0.0 0.0 0.0"/>
   </joint>
   <link name="scapphant">
      <inertial>
         <origin xyz="0.0 0.0 0.0" rpy="0.0 0.0 0.0"/>
         <mass value="0.001"/>
         <inertia ixx="1.0" iyy="1.0" izz="1.0" ixy="0" ixz="0" iyz="0"/>
      </inertial>
   </link>
   <joint type="fixed" name="scapula2scapphant_fixed">
      <parent link="scapula"/>
      <child link="scapphant"/>
      <origin xyz="-0.00955 -0.034 0.009" rpy="0.0 0.0 0.0"/>
   </joint>
   <link name="humphant">
      <inertial>
         <origin xyz="0.0 0.0 0.0" rpy="0.0 0.0 0.0"/>
         <mass value="0.001"/>
         <inertia ixx="1.0" iyy="1.0" izz="1.0" ixy="0" ixz="0" iyz="0"/>
      </inertial>
   </link>
   <joint type="fixed" name="scapphant2humphant_fixed">
      <parent link="scapphant"/>
      <child link="humphant"/>
      <origin xyz="0.0 0.0 0.0" rpy="0.0 0.0 0.0"/>
   </joint>
   <link name="humphant1">
      <inertial>
         <origin xyz="0.0 0.0 0.0" rpy="0.0 0.0 0.0"/>
         <mass value="0.001"/>
         <inertia ixx="1.0" iyy="1.0" izz="1.0" ixy="0" ixz="0" iyz="0"/>
      </inertial>
   </link>
   <joint type="fixed" name="humphant2humphant1_fixed">
      <parent link="humphant"/>
      <child link="humphant1"/>
      <origin xyz="0.0 0.0 0.0" rpy="0.0 0.0 1.57"/>
   </joint>
   <link name="humerus">
      <inertial>
         <origin xyz="0.018064 -0.140141 -0.012746" rpy="-1.3017194554109284 -1.1065529394509004 2.867524535734972"/>
         <mass value="1.99757"/>
         <inertia ixx="0.012857580877131061" iyy="0.012157596673713232" izz="0.0023926524491557173" ixy="0" ixz="0" iyz="0"/>
      </inertial>
      <visual name="humerus">
         <origin xyz="0.0007389972349670103 -0.13714039559722024 -0.003770500988989541" rpy="1.6098912975882635 0.02243248955460886 0.012029960406938711"/>
         <geometry>
            <mesh filename="file:///home/haochen/catkin_ws/src/relaxed_ik_ros1/relaxed_ik_core/configs/urdfs/meshes/humerus.stl"/>
         </geometry>
         <material name="white"/>
      </visual>
   </link>
   <joint type="fixed" name="humphant12humerus_fixed">
      <parent link="humphant1"/>
      <child link="humerus"/>
      <origin xyz="0.0 0.0 0.0" rpy="0.0 0.0 0.0"/>
   </joint>
   <link name="ulna">
      <inertial>
         <origin xyz="0.00971783 -0.0959509 0.024286" rpy="1.3102428002195294 -0.021372550920249367 0.07927170480809964"/>
         <mass value="1.1053"/>
         <inertia ixx="0.005436627883555106" iyy="0.005235205280106431" izz="0.000838046836338467" ixy="0" ixz="0" iyz="0"/>
      </inertial>
      <visual name="ulna">
         <origin xyz="-0.008342837461368435 -0.08169338490151855 0.01690709715204878" rpy="1.1308148835926248 -1.083447633621794 0.46827294641603834"/>
         <geometry>
            <mesh filename="file:///home/haochen/catkin_ws/src/relaxed_ik_ros1/relaxed_ik_core/configs/urdfs/meshes/ulna.stl"/>
         </geometry>
         <material name="white"/>
      </visual>
   </link>
   <joint type="fixed" name="humerus2ulna_fixed">
      <parent link="humerus"/>
      <child link="ulna"/>
      <origin xyz="0.0061 -0.2904 -0.0123" rpy="0.0 0.0 0.0"/>
   </joint>
   <link name="radius">
      <inertial>
         <origin xyz="0.0336341 -0.181559 0.0156" rpy="1.3776310565450496 -0.04605229961467372 0.09363153464595586"/>
         <mass value="0.23359"/>
         <inertia ixx="0.00044118407098437073" iyy="0.0004150877887965603" izz="0.0001" ixy="0" ixz="0" iyz="0"/>
      </inertial>
      <visual name="radius">
         <origin xyz="0.01778693872544466 -0.13556797901377618 0.015071064259036357" rpy="-1.235797775780969 -1.2534405203755958 2.938641555925341"/>
         <geometry>
            <mesh filename="file:///home/haochen/catkin_ws/src/relaxed_ik_ros1/relaxed_ik_core/configs/urdfs/meshes/radius.stl"/>
         </geometry>
         <material name="white"/>
      </visual>
   </link>
   <joint type="revolute" name="pro_sup">
      <parent link="ulna"/>
      <child link="radius"/>
      <origin xyz="0.0004 -0.011503 0.019999" rpy="0.0 0.0 0.0"/>
      <axis xyz="-0.01716099384176988 0.9926656437815011 -0.11966795705710145"/>
      <limit lower="-1.5708" upper="1.5708" effort="100" velocity="100"/>
   </joint>
   <link name="lunate">
      <inertial>
         <origin xyz="3.5729081885689077e-06 -1.8617728060419685e-06 1.787680193890675e-07" rpy="-0.36143622369692 -0.16023685527594544 0.6876895037329069"/>
         <mass value="0.0012000263535597198"/>
         <inertia ixx="0.0001" iyy="0.0001" izz="0.0001" ixy="0" ixz="0" iyz="0"/>
      </inertial>
      <visual name="lunate">
         <origin xyz="3.5729081885689077e-06 -1.8617728060419685e-06 1.787680193890675e-07" rpy="-0.36143622369691997 -0.16023685527594567 0.6876895037329067"/>
         <geometry>
            <mesh filename="file:///home/haochen/catkin_ws/src/relaxed_ik_ros1/relaxed_ik_core/configs/urdfs/meshes/lunate.stl"/>
         </geometry>
         <material name="white"/>
      </visual>
   </link>
   <link name="deviation_dummy">
      <inertial>
         <origin xyz="0.0 0.0 0.0" rpy="0.0 0.0 0.0"/>
         <mass value="0.001"/>
         <inertia ixx="1e-09" iyy="1e-09" izz="1e-09" ixy="0" ixz="0" iyz="0"/>
      </inertial>
   </link>
   <joint type="revolute" name="deviation">
      <parent link="radius"/>
      <child link="deviation_dummy"/>
      <origin xyz="0.018 -0.242 0.025" rpy="0.0 0.0 0.0"/>
      <axis xyz="0.0 0.0 1.0"/>
      <limit lower="-0.174533" upper="0.436332" effort="100" velocity="100"/>
   </joint>
   <joint type="revolute" name="flexion">
      <parent link="deviation_dummy"/>
      <child link="lunate"/>
      <origin xyz="0 0 0" rpy="0.0 0.0 0.0"/>
      <axis xyz="1.0 0.0 0.0"/>
      <limit lower="-0.785398" upper="0.785398" effort="100" velocity="100"/>
   </joint>
   <link name="scaphoid">
      <inertial>
         <origin xyz="0.0 0.0 0.0" rpy="0.0 0.0 0.0"/>
         <mass value="0.02"/>
         <inertia ixx="0.0001" iyy="0.0001" izz="0.0001" ixy="0" ixz="0" iyz="0"/>
      </inertial>
      <visual name="scaphoid">
         <origin xyz="-2.3838397997690175e-05 -9.018410708891066e-06 3.833897382858033e-05" rpy="-0.5692290431693718 -0.33878345041747715 0.21369142489696064"/>
         <geometry>
            <mesh filename="file:///home/haochen/catkin_ws/src/relaxed_ik_ros1/relaxed_ik_core/configs/urdfs/meshes/scaphoid.stl"/>
         </geometry>
         <material name="white"/>
      </visual>
   </link>
   <joint type="fixed" name="lunate2scaphoid_fixed">
      <parent link="lunate"/>
      <child link="scaphoid"/>
      <origin xyz="0.012345 -0.004464 -0.001254" rpy="0.0 0.0 0.0"/>
   </joint>
   <link name="pisiform">
      <inertial>
         <origin xyz="0.0 0.0 0.0" rpy="0.0 0.0 0.0"/>
         <mass value="0.02"/>
         <inertia ixx="0.0001" iyy="0.0001" izz="0.0001" ixy="0" ixz="0" iyz="0"/>
      </inertial>
      <visual name="pisiform">
         <origin xyz="0.0017780895273392433 -0.0009073903269969469 -7.190186304977116e-05" rpy="1.2462055088005255 0.49559439583995424 -0.34929645069987836"/>
         <geometry>
            <mesh filename="file:///home/haochen/catkin_ws/src/relaxed_ik_ros1/relaxed_ik_core/configs/urdfs/meshes/pisiform.stl"/>
         </geometry>
         <material name="white"/>
      </visual>
   </link>
   <joint type="fixed" name="lunate2pisiform_fixed">
      <parent link="lunate"/>
      <child link="pisiform"/>
      <origin xyz="-0.013388 -0.009886 -0.010593" rpy="0.0 0.0 0.0"/>
   </joint>
   <link name="triquetrum">
      <inertial>
         <origin xyz="0.0 0.0 0.0" rpy="0.0 0.0 0.0"/>
         <mass value="0.02"/>
         <inertia ixx="0.0001" iyy="0.0001" izz="0.0001" ixy="0" ixz="0" iyz="0"/>
      </inertial>
      <visual name="triquetrum">
         <origin xyz="5.930790822756372e-07 -1.1225602601593567e-06 -3.3935291609719996e-06" rpy="1.9269139677822995 -0.29745876180457564 -0.5516387254770375"/>
         <geometry>
            <mesh filename="file:///home/haochen/catkin_ws/src/relaxed_ik_ros1/relaxed_ik_core/configs/urdfs/meshes/triquetrum.stl"/>
         </geometry>
         <material name="white"/>
      </visual>
   </link>
   <joint type="fixed" name="lunate2triquetrum_fixed">
      <parent link="lunate"/>
      <child link="triquetrum"/>
      <origin xyz="-0.010784 -0.007499 -0.001289" rpy="0.0 0.0 0.0"/>
   </joint>
   <link name="capitate">
      <inertial>
         <origin xyz="2.4997529376086936e-06 -4.319736123192584e-06 1.3404175140860993e-06" rpy="1.2103081004613072 -0.2920747955988763 -0.020398215496376104"/>
         <mass value="0.001912230829037991"/>
         <inertia ixx="0.0001" iyy="0.0001" izz="0.0001" ixy="0" ixz="0" iyz="0"/>
      </inertial>
      <visual name="capitate">
         <origin xyz="2.4997529376086936e-06 -4.319736123192584e-06 1.3404175140860993e-06" rpy="1.2103081004613072 -0.29207479559887606 -0.020398215496375882"/>
         <geometry>
            <mesh filename="file:///home/haochen/catkin_ws/src/relaxed_ik_ros1/relaxed_ik_core/configs/urdfs/meshes/capitate.stl"/>
         </geometry>
         <material name="white"/>
      </visual>
   </link>
   <joint type="fixed" name="lunate2capitate_fixed">
      <parent link="lunate"/>
      <child link="capitate"/>
      <origin xyz="0.003992 -0.015054 0.002327" rpy="0.0 0.0 0.0"/>
   </joint>
   <link name="trapezium">
      <inertial>
         <origin xyz="0.0 0.0 0.0" rpy="0.0 0.0 0.0"/>
         <mass value="0.02"/>
         <inertia ixx="0.0001" iyy="0.0001" izz="0.0001" ixy="0" ixz="0" iyz="0"/>
      </inertial>
      <visual name="trapezium">
         <origin xyz="-5.679888633744862e-06 1.5277743172746618e-06 -7.338957239381493e-07" rpy="-0.25650854392346234 -0.8000548292338777 2.2561533548010577"/>
         <geometry>
            <mesh filename="file:///home/haochen/catkin_ws/src/relaxed_ik_ros1/relaxed_ik_core/configs/urdfs/meshes/trapezium.stl"/>
         </geometry>
         <material name="white"/>
      </visual>
   </link>
   <joint type="fixed" name="capitate2trapezium_fixed">
      <parent link="capitate"/>
      <child link="trapezium"/>
      <origin xyz="0.015293 -0.004569 -0.010308" rpy="0.0 0.0 0.0"/>
   </joint>
   <link name="firstmc">
      <inertial>
         <origin xyz="0.0078 -0.0147 -0.006" rpy="3.0533511710139978 -1.1531262190237377 -0.9287642901648694"/>
         <mass value="0.016"/>
         <inertia ixx="0.0001" iyy="0.0001" izz="0.0001" ixy="0" ixz="0" iyz="0"/>
      </inertial>
      <visual name="1mc">
         <origin xyz="0.009056264316583781 -0.014469189773066942 -0.005718652010116575" rpy="2.54268450933459 -1.0993750206052635 -0.39879076290649373"/>
         <geometry>
            <mesh filename="file:///home/haochen/catkin_ws/src/relaxed_ik_ros1/relaxed_ik_core/configs/urdfs/meshes/1mc.stl"/>
         </geometry>
         <material name="white"/>
      </visual>
   </link>
   <link name="cmc_abduction_dummy">
      <inertial>
         <origin xyz="0.0 0.0 0.0" rpy="0.0 0.0 0.0"/>
         <mass value="0.001"/>
         <inertia ixx="1e-09" iyy="1e-09" izz="1e-09" ixy="0" ixz="0" iyz="0"/>
      </inertial>
   </link>
   <joint type="revolute" name="cmc_abduction">
      <parent link="trapezium"/>
      <child link="cmc_abduction_dummy"/>
      <origin xyz="0.0072 -0.0054 -0.0025" rpy="0.0 0.0 0.0"/>
      <axis xyz="-0.04239899057782176 -0.66528585215587 0.7453838343559777"/>
      <limit lower="-0.5" upper="0.78" effort="100" velocity="100"/>
   </joint>
   <joint type="revolute" name="cmc_flexion">
      <parent link="cmc_abduction_dummy"/>
      <child link="firstmc"/>
      <origin xyz="0 0 0" rpy="0.0 0.0 0.0"/>
      <axis xyz="0.49555701495937987 0.7317360220889156 0.467959014126279"/>
      <limit lower="-0.78" upper="0.7" effort="100" velocity="100"/>
   </joint>
   <link name="proximal_thumb">
      <inertial>
         <origin xyz="0.0096 -0.0163 -0.0063" rpy="2.148220805412432 0.11359933944429357 1.373497666106347"/>
         <mass value="0.0079"/>
         <inertia ixx="0.0001" iyy="0.0001" izz="0.0001" ixy="0" ixz="0" iyz="0"/>
      </inertial>
      <visual name="thumbprox">
         <origin xyz="0.00854743568645298 -0.015081378924573417 -0.005624693621316211" rpy="1.9071441771509634 -0.2854725307188819 0.4039595542013209"/>
         <geometry>
            <mesh filename="file:///home/haochen/catkin_ws/src/relaxed_ik_ros1/relaxed_ik_core/configs/urdfs/meshes/thumbprox.stl"/>
         </geometry>
         <material name="white"/>
      </visual>
   </link>
   <joint type="revolute" name="mp_flexion">
      <parent link="firstmc"/>
      <child link="proximal_thumb"/>
      <origin xyz="0.0165 -0.0292 -0.0127" rpy="0.0 0.0 0.0"/>
      <axis xyz="-0.08429499542560574 -0.20348798895741932 0.9754419470661809"/>
      <limit lower="-0.785398" upper="0.698132" effort="100" velocity="100"/>
   </joint>
   <link name="distal_thumb">
      <inertial>
         <origin xyz="0.0056 -0.0104 -0.0044" rpy="2.1862764689261063 -0.7853978566574384 -6.130054173159039e-07"/>
         <mass value="0.003"/>
         <inertia ixx="0.0001" iyy="0.0001" izz="0.0001" ixy="0" ixz="0" iyz="0"/>
      </inertial>
      <visual name="thumbdist">
         <origin xyz="0.004233976934888571 -0.009082502024479045 -0.0036233815766157224" rpy="1.956804989110012 -0.2974126811291695 0.40556684884240524"/>
         <geometry>
            <mesh filename="file:///home/haochen/catkin_ws/src/relaxed_ik_ros1/relaxed_ik_core/configs/urdfs/meshes/thumbdist.stl"/>
         </geometry>
         <material name="white"/>
      </visual>
   </link>
   <joint type="revolute" name="ip_flexion">
      <parent link="proximal_thumb"/>
      <child link="distal_thumb"/>
      <origin xyz="0.014 -0.0259 -0.0101" rpy="0.0 0.0 0.0"/>
      <axis xyz="-0.050102005752161505 -0.4796230550650465 0.876043100577638"/>
      <limit lower="-1.309" upper="0.436332" effort="100" velocity="100"/>
   </joint>
   <link name="trapezoid">
      <inertial>
         <origin xyz="0.0 0.0 0.0" rpy="0.0 0.0 0.0"/>
         <mass value="0.02"/>
         <inertia ixx="0.0001" iyy="0.0001" izz="0.0001" ixy="0" ixz="0" iyz="0"/>
      </inertial>
      <visual name="trapezoid">
         <origin xyz="1.3738754173765188e-06 -1.4770538374651388e-06 1.891333122868397e-07" rpy="0.27598761251820697 0.5558008487263413 0.19209924739735612"/>
         <geometry>
            <mesh filename="file:///home/haochen/catkin_ws/src/relaxed_ik_ros1/relaxed_ik_core/configs/urdfs/meshes/trapezoid.stl"/>
         </geometry>
         <material name="white"/>
      </visual>
   </link>
   <joint type="fixed" name="capitate2trapezoid_fixed">
      <parent link="capitate"/>
      <child link="trapezoid"/>
      <origin xyz="0.009143 -0.004062 -0.002464" rpy="0.0 0.0 0.0"/>
   </joint>
   <link name="hamate">
      <inertial>
         <origin xyz="0.0 0.0 0.0" rpy="0.0 0.0 0.0"/>
         <mass value="0.02"/>
         <inertia ixx="0.0001" iyy="0.0001" izz="0.0001" ixy="0" ixz="0" iyz="0"/>
      </inertial>
      <visual name="hamate">
         <origin xyz="-1.1482893173857308e-05 -1.3737940466853783e-06 1.520742004524574e-06" rpy="1.941141541594031 -0.4553846643318562 -0.6664160632978575"/>
         <geometry>
            <mesh filename="file:///home/haochen/catkin_ws/src/relaxed_ik_ros1/relaxed_ik_core/configs/urdfs/meshes/hamate.stl"/>
         </geometry>
         <material name="white"/>
      </visual>
   </link>
   <joint type="fixed" name="capitate2hamate_fixed">
      <parent link="capitate"/>
      <child link="hamate"/>
      <origin xyz="-0.010969 -0.002495 -0.00075" rpy="0.0 0.0 0.0"/>
   </joint>
   <link name="secondmc">
      <inertial>
         <origin xyz="0.0 0.0 0.0" rpy="0.0 0.0 0.0"/>
         <mass value="0.02"/>
         <inertia ixx="0.0001" iyy="0.0001" izz="0.0001" ixy="0" ixz="0" iyz="0"/>
      </inertial>
      <visual name="2mc">
         <origin xyz="-0.00010482465471356576 0.00012638710442843635 -0.00013983506463650922" rpy="-1.2288611407496322 -1.0576482637579705 2.9957695490133696"/>
         <geometry>
            <mesh filename="file:///home/haochen/catkin_ws/src/relaxed_ik_ros1/relaxed_ik_core/configs/urdfs/meshes/2mc.stl"/>
         </geometry>
         <material name="white"/>
      </visual>
   </link>
   <joint type="fixed" name="capitate2secondmc_fixed">
      <parent link="capitate"/>
      <child link="secondmc"/>
      <origin xyz="0.014685 -0.03762 0.005032" rpy="0.0 0.0 0.0"/>
   </joint>
   <link name="proxph2">
      <inertial>
         <origin xyz="0.0 0.0 0.0" rpy="0.0 0.0 0.0"/>
         <mass value="0.01"/>
         <inertia ixx="0.0001" iyy="0.0001" izz="0.0001" ixy="0" ixz="0" iyz="0"/>
      </inertial>
      <visual name="2proxph">
         <origin xyz="0.004275685829307829 -0.022419093299298025 0.004665213793071962" rpy="0.9709003616295141 -1.2746318403785954 0.7458529037079816"/>
         <geometry>
            <mesh filename="file:///home/haochen/catkin_ws/src/relaxed_ik_ros1/relaxed_ik_core/configs/urdfs/meshes/2proxph.stl"/>
         </geometry>
         <material name="white"/>
      </visual>
   </link>
   <link name="mcp2_flexion_dummy">
      <inertial>
         <origin xyz="0.0 0.0 0.0" rpy="0.0 0.0 0.0"/>
         <mass value="0.001"/>
         <inertia ixx="1e-09" iyy="1e-09" izz="1e-09" ixy="0" ixz="0" iyz="0"/>
      </inertial>
   </link>
   <joint type="revolute" name="mcp2_flexion">
      <parent link="secondmc"/>
      <child link="mcp2_flexion_dummy"/>
      <origin xyz="0.003501 -0.028243 0.00362" rpy="0.0 0.0 0.0"/>
      <axis xyz="0.9950125359914347 0.09974995348316616 0.0"/>
      <limit lower="0.0" upper="1.5708" effort="100" velocity="100"/>
   </joint>
   <joint type="revolute" name="mcp2_abduction">
      <parent link="mcp2_flexion_dummy"/>
      <child link="proxph2"/>
      <origin xyz="0 0 0" rpy="0.0 0.0 0.0"/>
      <axis xyz="-0.05499898007863053 0.08589896888623946 0.994784639675639"/>
      <limit lower="-0.261799" upper="0.261799" effort="100" velocity="100"/>
   </joint>
   <link name="midph2">
      <inertial>
         <origin xyz="0.0 0.0 0.0" rpy="0.0 0.0 0.0"/>
         <mass value="0.003"/>
         <inertia ixx="0.0001" iyy="0.0001" izz="0.0001" ixy="0" ixz="0" iyz="0"/>
      </inertial>
      <visual name="2midph">
         <origin xyz="0.0017277519451553412 -0.013616297359733789 0.0003856873530481467" rpy="1.158904539208336 -1.3504746728052996 0.5306663319235637"/>
         <geometry>
            <mesh filename="file:///home/haochen/catkin_ws/src/relaxed_ik_ros1/relaxed_ik_core/configs/urdfs/meshes/2midph.stl"/>
         </geometry>
         <material name="white"/>
      </visual>
   </link>
   <joint type="revolute" name="pm2_flexion">
      <parent link="proxph2"/>
      <child link="midph2"/>
      <origin xyz="0.00751 -0.041273 0.007326" rpy="0.0 0.0 0.0"/>
      <axis xyz="0.975170276468341 0.09983342830355166 -0.19767705604297942"/>
      <limit lower="0.0" upper="1.5708" effort="100" velocity="100"/>
   </joint>
   <link name="distph2">
      <inertial>
         <origin xyz="0.0 0.0 0.0" rpy="0.0 0.0 0.0"/>
         <mass value="0.002"/>
         <inertia ixx="0.0001" iyy="0.0001" izz="0.0001" ixy="0" ixz="0" iyz="0"/>
      </inertial>
      <visual name="2distph">
         <origin xyz="0.0010685158082065728 -0.008498728936623087 0.0002992242466598517" rpy="0.4005731781857966 -1.4650113856479963 1.3152228545301379"/>
         <geometry>
            <mesh filename="file:///home/haochen/catkin_ws/src/relaxed_ik_ros1/relaxed_ik_core/configs/urdfs/meshes/2distph.stl"/>
         </geometry>
         <material name="white"/>
      </visual>
   </link>
   <joint type="revolute" name="md2_flexion">
      <parent link="midph2"/>
      <child link="distph2"/>
      <origin xyz="0.003333 -0.024888 0.00122" rpy="0.0 0.0 0.0"/>
      <axis xyz="0.9950041652843545 0.09983341658375151 0.0"/>
      <limit lower="0.0" upper="1.5708" effort="100" velocity="100"/>
   </joint>
   <link name="thirdmc">
      <inertial>
         <origin xyz="0.0 0.0 0.0" rpy="0.0 0.0 0.0"/>
         <mass value="0.02"/>
         <inertia ixx="0.0001" iyy="0.0001" izz="0.0001" ixy="0" ixz="0" iyz="0"/>
      </inertial>
      <visual name="3mc">
         <origin xyz="1.2224798849698734e-05 0.0005168737374986281 -0.0002408104212366876" rpy="1.4450266262998412 0.1803584102818272 -0.007490416792627297"/>
         <geometry>
            <mesh filename="file:///home/haochen/catkin_ws/src/relaxed_ik_ros1/relaxed_ik_core/configs/urdfs/meshes/3mc.stl"/>
         </geometry>
         <material name="white"/>
      </visual>
   </link>
   <joint type="fixed" name="capitate2thirdmc_fixed">
      <parent link="capitate"/>
      <child link="thirdmc"/>
      <origin xyz="0.000477 -0.039239 0.007377" rpy="0.0 0.0 0.0"/>
   </joint>
   <link name="proxph3">
      <inertial>
         <origin xyz="0.0 0.0 0.0" rpy="0.0 0.0 0.0"/>
         <mass value="0.01"/>
         <inertia ixx="0.0001" iyy="0.0001" izz="0.0001" ixy="0" ixz="0" iyz="0"/>
      </inertial>
      <visual name="3proxph">
         <origin xyz="0.0010734969620727643 -0.023288394738447946 0.004509986848183467" rpy="0.356540169428286 -1.441344055628468 1.227103977107489"/>
         <geometry>
            <mesh filename="file:///home/haochen/catkin_ws/src/relaxed_ik_ros1/relaxed_ik_core/configs/urdfs/meshes/3proxph.stl"/>
         </geometry>
         <material name="white"/>
      </visual>
   </link>
   <link name="mcp3_flexion_dummy">
      <inertial>
         <origin xyz="0.0 0.0 0.0" rpy="0.0 0.0 0.0"/>
         <mass value="0.001"/>
         <inertia ixx="1e-09" iyy="1e-09" izz="1e-09" ixy="0" ixz="0" iyz="0"/>
      </inertial>
   </link>
   <joint type="revolute" name="mcp3_flexion">
      <parent link="thirdmc"/>
      <child link="mcp3_flexion_dummy"/>
      <origin xyz="0.00024 -0.02629 0.001778" rpy="0.0 0.0 0.0"/>
      <axis xyz="0.9800666589123603 0.0 0.19866893085825738"/>
      <limit lower="0.0" upper="1.5708" effort="100" velocity="100"/>
   </joint>
   <joint type="revolute" name="mcp3_abduction">
      <parent link="mcp3_flexion_dummy"/>
      <child link="proxph3"/>
      <origin xyz="0 0 0" rpy="0.0 0.0 0.0"/>
      <axis xyz="-0.19866893085825738 0.0 0.9800666589123603"/>
      <limit lower="-0.261799" upper="0.261799" effort="100" velocity="100"/>
   </joint>
   <link name="midph3">
      <inertial>
         <origin xyz="0.0 0.0 0.0" rpy="0.0 0.0 0.0"/>
         <mass value="0.002"/>
         <inertia ixx="0.0001" iyy="0.0001" izz="0.0001" ixy="0" ixz="0" iyz="0"/>
      </inertial>
      <visual name="3midph">
         <origin xyz="0.0006816078760314237 -0.014875938368986357 0.001587685371803658" rpy="-0.7901456653983332 -1.4979259934357858 2.4117147631811826"/>
         <geometry>
            <mesh filename="file:///home/haochen/catkin_ws/src/relaxed_ik_ros1/relaxed_ik_core/configs/urdfs/meshes/3midph.stl"/>
         </geometry>
         <material name="white"/>
      </visual>
   </link>
   <joint type="revolute" name="pm3_flexion">
      <parent link="proxph3"/>
      <child link="midph3"/>
      <origin xyz="0.00165 -0.044211 0.00623" rpy="0.0 0.0 0.0"/>
      <axis xyz="1.0 0.0 0.0"/>
      <limit lower="0.0" upper="1.5708" effort="100" velocity="100"/>
   </joint>
   <link name="distph3">
      <inertial>
         <origin xyz="0.0 0.0 0.0" rpy="0.0 0.0 0.0"/>
         <mass value="0.002"/>
         <inertia ixx="0.0001" iyy="0.0001" izz="0.0001" ixy="0" ixz="0" iyz="0"/>
      </inertial>
      <visual name="3distph">
         <origin xyz="0.0006273508355478594 -0.008558888636208259 -3.248103020591859e-05" rpy="0.4079397820603109 -1.4851549016387633 1.2108481043436288"/>
         <geometry>
            <mesh filename="file:///home/haochen/catkin_ws/src/relaxed_ik_ros1/relaxed_ik_core/configs/urdfs/meshes/3distph.stl"/>
         </geometry>
         <material name="white"/>
      </visual>
   </link>
   <joint type="revolute" name="md3_flexion">
      <parent link="midph3"/>
      <child link="distph3"/>
      <origin xyz="0.001365 -0.029047 0.001954" rpy="0.0 0.0 0.0"/>
      <axis xyz="1.0 0.0 0.0"/>
      <limit lower="0.0" upper="1.5708" effort="100" velocity="100"/>
   </joint>
   <link name="fourthmc">
      <inertial>
         <origin xyz="0.0 0.0 0.0" rpy="0.0 0.0 0.0"/>
         <mass value="0.02"/>
         <inertia ixx="0.0001" iyy="0.0001" izz="0.0001" ixy="0" ixz="0" iyz="0"/>
      </inertial>
      <visual name="4mc">
         <origin xyz="4.3801331849671294e-05 0.0005319429897597941 -0.00016676819956183388" rpy="1.5268660941250807 -0.37727025049358964 -0.07031755099911208"/>
         <geometry>
            <mesh filename="file:///home/haochen/catkin_ws/src/relaxed_ik_ros1/relaxed_ik_core/configs/urdfs/meshes/4mc.stl"/>
         </geometry>
         <material name="white"/>
      </visual>
   </link>
   <joint type="fixed" name="capitate2fourthmc_fixed">
      <parent link="capitate"/>
      <child link="fourthmc"/>
      <origin xyz="-0.012046 -0.040519 0.003513" rpy="0.0 0.0 0.0"/>
   </joint>
   <link name="proxph4">
      <inertial>
         <origin xyz="0.0 0.0 0.0" rpy="0.0 0.0 0.0"/>
         <mass value="0.01"/>
         <inertia ixx="0.0001" iyy="0.0001" izz="0.0001" ixy="0" ixz="0" iyz="0"/>
      </inertial>
      <visual name="4proxph">
         <origin xyz="-0.002123116899704132 -0.02159195456528691 0.0013317426811762035" rpy="-1.48206161630986 -1.18151227222004 2.9619189954922263"/>
         <geometry>
            <mesh filename="file:///home/haochen/catkin_ws/src/relaxed_ik_ros1/relaxed_ik_core/configs/urdfs/meshes/4proxph.stl"/>
         </geometry>
         <material name="white"/>
      </visual>
   </link>
   <link name="mcp4_flexion_dummy">
      <inertial>
         <origin xyz="0.0 0.0 0.0" rpy="0.0 0.0 0.0"/>
         <mass value="0.001"/>
         <inertia ixx="1e-09" iyy="1e-09" izz="1e-09" ixy="0" ixz="0" iyz="0"/>
      </inertial>
   </link>
   <joint type="revolute" name="mcp4_flexion">
      <parent link="fourthmc"/>
      <child link="mcp4_flexion_dummy"/>
      <origin xyz="-0.00183 -0.023689 -0.000173" rpy="0.0 0.0 0.0"/>
      <axis xyz="0.9004469005163807 0.0 0.4349659519438768"/>
      <limit lower="0.0" upper="1.5708" effort="100" velocity="100"/>
   </joint>
   <joint type="revolute" name="mcp4_abduction">
      <parent link="mcp4_flexion_dummy"/>
      <child link="proxph4"/>
      <origin xyz="0 0 0" rpy="0.0 0.0 0.0"/>
      <axis xyz="-0.4349659519438768 0.0 0.9004469005163807"/>
      <limit lower="-0.261799" upper="0.261799" effort="100" velocity="100"/>
   </joint>
   <link name="midph4">
      <inertial>
         <origin xyz="0.0 0.0 0.0" rpy="0.0 0.0 0.0"/>
         <mass value="0.003"/>
         <inertia ixx="0.0001" iyy="0.0001" izz="0.0001" ixy="0" ixz="0" iyz="0"/>
      </inertial>
      <visual name="4midph">
         <origin xyz="-0.0016100837561235258 -0.013115120811561626 0.000598209506780814" rpy="-1.519915798531982 -1.1738041813724047 3.0280961456242403"/>
         <geometry>
            <mesh filename="file:///home/haochen/catkin_ws/src/relaxed_ik_ros1/relaxed_ik_core/configs/urdfs/meshes/4midph.stl"/>
         </geometry>
         <material name="white"/>
      </visual>
   </link>
   <joint type="revolute" name="pm4_flexion">
      <parent link="proxph4"/>
      <child link="midph4"/>
      <origin xyz="-0.003528 -0.040255 0.001345" rpy="0.0 0.0 0.0"/>
      <axis xyz="0.9210611176908945 0.0 0.389418049758868"/>
      <limit lower="0.0" upper="1.5708" effort="100" velocity="100"/>
   </joint>
   <link name="distph4">
      <inertial>
         <origin xyz="0.0 0.0 0.0" rpy="0.0 0.0 0.0"/>
         <mass value="0.002"/>
         <inertia ixx="0.0001" iyy="0.0001" izz="0.0001" ixy="0" ixz="0" iyz="0"/>
      </inertial>
      <visual name="4distph">
         <origin xyz="-0.0006504341677935862 -0.00885048406939273 0.001052355697415125" rpy="-1.321204456518454 -0.9778994340229656 2.822433565024708"/>
         <geometry>
            <mesh filename="file:///home/haochen/catkin_ws/src/relaxed_ik_ros1/relaxed_ik_core/configs/urdfs/meshes/4distph.stl"/>
         </geometry>
         <material name="white"/>
      </visual>
   </link>
   <joint type="revolute" name="md4_flexion">
      <parent link="midph4"/>
      <child link="distph4"/>
      <origin xyz="-0.002317 -0.024789 0.000563" rpy="0.0 0.0 0.0"/>
      <axis xyz="0.8253359582957751 0.0 0.5646419714686419"/>
      <limit lower="0.0" upper="1.5708" effort="100" velocity="100"/>
   </joint>
   <link name="fifthmc">
      <inertial>
         <origin xyz="0.0 0.0 0.0" rpy="0.0 0.0 0.0"/>
         <mass value="0.02"/>
         <inertia ixx="0.0001" iyy="0.0001" izz="0.0001" ixy="0" ixz="0" iyz="0"/>
      </inertial>
      <visual name="5mc">
         <origin xyz="0.0001946755913526482 0.0004185145324013182 -0.00012864902693672213" rpy="1.6537260233892077 -1.161764483067726 -0.20407074680325432"/>
         <geometry>
            <mesh filename="file:///home/haochen/catkin_ws/src/relaxed_ik_ros1/relaxed_ik_core/configs/urdfs/meshes/5mc.stl"/>
         </geometry>
         <material name="white"/>
      </visual>
   </link>
   <joint type="fixed" name="capitate2fifthmc_fixed">
      <parent link="capitate"/>
      <child link="fifthmc"/>
      <origin xyz="-0.021896 -0.034683 -0.004218" rpy="0.0 0.0 0.0"/>
   </joint>
   <link name="proxph5">
      <inertial>
         <origin xyz="0.0 0.0 0.0" rpy="0.0 0.0 0.0"/>
         <mass value="0.005"/>
         <inertia ixx="0.0001" iyy="0.0001" izz="0.0001" ixy="0" ixz="0" iyz="0"/>
      </inertial>
      <visual name="5proxph">
         <origin xyz="-0.0033059754675208463 -0.01932150249608627 -0.0011939106840236087" rpy="-1.6611066988120482 -0.7864199858927242 3.0739930387917926"/>
         <geometry>
            <mesh filename="file:///home/haochen/catkin_ws/src/relaxed_ik_ros1/relaxed_ik_core/configs/urdfs/meshes/5proxph.stl"/>
         </geometry>
         <material name="white"/>
      </visual>
   </link>
   <link name="mcp5_flexion_dummy">
      <inertial>
         <origin xyz="0.0 0.0 0.0" rpy="0.0 0.0 0.0"/>
         <mass value="0.001"/>
         <inertia ixx="1e-09" iyy="1e-09" izz="1e-09" ixy="0" ixz="0" iyz="0"/>
      </inertial>
   </link>
   <joint type="revolute" name="mcp5_flexion">
      <parent link="fifthmc"/>
      <child link="mcp5_flexion_dummy"/>
      <origin xyz="-0.001597 -0.021431 -0.001496" rpy="0.0 0.0 0.0"/>
      <axis xyz="0.8253359582957751 0.0 0.5646419714686419"/>
      <limit lower="0.0" upper="1.5708" effort="100" velocity="100"/>
   </joint>
   <joint type="revolute" name="mcp5_abduction">
      <parent link="mcp5_flexion_dummy"/>
      <child link="proxph5"/>
      <origin xyz="0 0 0" rpy="0.0 0.0 0.0"/>
      <axis xyz="-0.5646419714686419 0.0 0.8253359582957751"/>
      <limit lower="-0.261799" upper="0.261799" effort="100" velocity="100"/>
   </joint>
   <link name="midph5">
      <inertial>
         <origin xyz="0.0 0.0 0.0" rpy="0.0 0.0 0.0"/>
         <mass value="0.002"/>
         <inertia ixx="0.0001" iyy="0.0001" izz="0.0001" ixy="0" ixz="0" iyz="0"/>
      </inertial>
      <visual name="5midph">
         <origin xyz="-0.0016154172076035664 -0.011770584963886376 -0.0013380748651654446" rpy="-1.6670559885353535 -0.8258793506677454 3.062789911553409"/>
         <geometry>
            <mesh filename="file:///home/haochen/catkin_ws/src/relaxed_ik_ros1/relaxed_ik_core/configs/urdfs/meshes/5midph.stl"/>
         </geometry>
         <material name="white"/>
      </visual>
   </link>
   <joint type="revolute" name="pm5_flexion">
      <parent link="proxph5"/>
      <child link="midph5"/>
      <origin xyz="-0.005279 -0.035563 -0.002879" rpy="0.0 0.0 0.0"/>
      <axis xyz="0.8253359582957751 0.0 0.5646419714686419"/>
      <limit lower="0.0" upper="1.5708" effort="100" velocity="100"/>
   </joint>
   <link name="distph5">
      <inertial>
         <origin xyz="0.0 0.0 0.0" rpy="0.0 0.0 0.0"/>
         <mass value="0.001"/>
         <inertia ixx="0.0001" iyy="0.0001" izz="0.0001" ixy="0" ixz="0" iyz="0"/>
      </inertial>
      <visual name="5distph">
         <origin xyz="-0.0011480584679722193 -0.007831273015629098 -0.0008071896151273049" rpy="-1.6813257389173484 -0.8100596470207786 3.0498283398048334"/>
         <geometry>
            <mesh filename="file:///home/haochen/catkin_ws/src/relaxed_ik_ros1/relaxed_ik_core/configs/urdfs/meshes/5distph.stl"/>
         </geometry>
         <material name="white"/>
      </visual>
   </link>
   <joint type="revolute" name="md5_flexion">
      <parent link="midph5"/>
      <child link="distph5"/>
      <origin xyz="-0.002871 -0.020677 -0.002243" rpy="0.0 0.0 0.0"/>
      <axis xyz="0.6431121484444494 -0.22680405235137102 0.7314141688265008"/>
      <limit lower="0.0" upper="1.5708" effort="100" velocity="100"/>
   </joint>
   <material name="white">
      <color rgba="1 1 1 1"/>
   </material>
</robot>
